Workbook
Name Owner: [1]Catalogos!$B$2:$B$9
Name Owner: Catalogos!$B$2:$B$9
Name Sts_2: [1]Catalogos!$G$2:$G$6
Name Sts_2: Catalogos!$G$2:$G$6
Name StsAct: [1]Catalogos!$D$2:$D$11
Name StsAct: Catalogos!$D$2:$D$11

Sheet pendientes27102025
B2: Area | C2: Reporte | D2: Pendiente | E2: Observaciones
B3: Riesgos | C3: CFEN | D3: Mapeo | E3: Reunión oct 27
C4: R35
C5: PORCENTAJE_GARANTIA_PERSONAL | D5: Validación campos | E5: Pendiente
C6: PORCENTAJE_GARANTIA
C7: PRELACION_GAR
C8: R-0419 | D8: Revisión | E8: Generar reunión Contabilidad para definir responsable
B9: Contabilidad | C9: R-0420 | D9: Mapeo | E9: Operaciones recabó información falta solicitar info a Contabilidad*
C10: IPAB | E10: Pendiente de recibir el mapeo del layout
C11: ACM II_ADIC | D11: Validacion Usuario | E11: Pendiente de recibir retroalimentación sobre layouts desarrollados
C12: ACM II-Mapeo
C13: CATALOGO MINIMO
C14: CONCILIACIONES
C15: INVERSIONES PERMANENTES

Sheet Detalle1
A1: Detalles para Rprts - Azure: 03. DESARROLLO
A3: Carpeta | B3: Area | C3: Responsable | D3: Azure | E3: Pestañas | F3: Layout | G3: Estatus | H3: Comentarios | I3: Revision VoBo Usuario | J3: Actualizacion | K3: EstatusAct | L3: Sts2 | M3: Desarrollo | N3: AreaApoyo | O3: Obs Add | P3: Obs Add2 | Q3: NO APLICA | R3: MOTIVO
A4: Cartera | B4: Operaciones Captacion y credito | C4: Luis Alberto | D4: 03. DESARROLLO | E4: CLIENTES_POR_PRODUCTO | F4: R2450_51_52_CLIENTES POR PRODUCTO_V0.5 -- R2450 - R2451 - R2452 (CREDITO) (1) | G4: Listo | H4: Ntt, ya se reviso txt por usuario VoBo | I4: Estructura | K4: DES-Desarrollo Txt | L4: Validar | M4: Interno | N4: TI | O4: 2a vuelta US | P4: Integrar en un layout captación y crédito
A5: Cartera | B5: Operaciones Credito | C5: Luis Alberto | D5: 03. DESARROLLO | E5: CONSUMO | F5: V1.05_Credito_IFRS9_Consumo_Completo VF (2) | G5: Listo | H5: Se tiene la estructura construida y se integraron los datos con los que se cuenta, aun no se cuenta con todo el universo(Fuentes externas | I5: Estructura | K5: DES-Desarrollo Txt | M5: Interno | N5: TI
A6: Cartera | B6: Operaciones Credito | C6: Luis Alberto | D6: 03. DESARROLLO | E6: CREDITO | F6: V1.05_Layouts CREDITO Bancos IFRS (Comercial) (1) | G6: Listo | H6: Se tiene la estructura construida y se integraron los datos con los que se cuenta, aun no se cuenta con todo el universo(Fuentes externas | I6: Estructura | K6: DES-Desarrollo Txt | M6: Interno | N6: TI
A7: Operativos | B7: Operaciones Captacion | C7: Luis Alberto | D7: 03. DESARROLLO | E7: TITULARES GARANTIZADOS | F7: R2423_IFRS9_Titulares_Garantizados_V0.4 -- R2423 | G7: No mapeado | H7: NTT | K7: DES-Desarrollo Txt | L7: Ext NTT | M7: Externo | N7: Operaciones
A8: Cartera | B8: Operaciones Credito | C8: Luis Alberto | D8: 03. DESARROLLO | E8: CREDITO_GARANTIA | F8: V1.05_Layouts CREDITO Bancos IFRS (Comercial) (1) | G8: Listo | H8: Se tiene la estructura construida y se integraron los datos con los que se cuenta, aun no se cuenta con todo el universo(Fuentes externas | I8: Estructura | J8: PORCENTAJE_GARANTIA | Tiene Un campo x validar Riesgos | K8: DES-Desarrollo Txt | M8: Interno | N8: Riesgos
A9: Cartera | B9: Operaciones Credito | C9: Luis Alberto | D9: 03. DESARROLLO | E9: CREDITO_GARANTIA_PERSONAL | F9: V1.05_Layouts CREDITO Bancos IFRS (Comercial) (1) | G9: Listo | H9: Se tiene la estructura construida y se integraron los datos con los que se cuenta, aun no se cuenta con todo el universo(Fuentes externas | I9: Estructura | J9: PORCENTAJE_GARANTIA_PERS | Tiene Un campo x validar Riesgos | K9: DES-Desarrollo Txt | M9: Interno | N9: Riesgos
A10: Captacion | B10: Operaciones Captacion | C10: Luis Alberto | D10: 03. DESARROLLO | E10: ENT_CAJA_CAPTACION | F10: Layout CCV BW -- CCV | G10: Listo | H10: Ntt, ya se reviso txt por usuario VoBo | I10: Estructura y universo | J10: Validar con usuario si aplican | K10: DES-Desarrollo Txt | L10: Ext NTT | M10: Interno | N10: Operaciones | O10: Se menciona a NTT
A11: Captacion | B11: Operaciones Captacion | C11: Luis Alberto | D11: 03. DESARROLLO | E11: FILE_CAPTACION | F11: Layout Captacion_V3 -- CRI - R08 - OCIM_II | G11: Listo | H11: Ntt, ya se reviso txt por usuario VoBo Estructura | I11: Estructura y universo | J11: 20260108 -- NTT franja fronteriza en cero ION reenvió catalogo | K11: DES-Desarrollo Txt | L11: Ext NTT | M11: Interno | N11: TI | O11: Se requiera info actualizada congelando sistema para validacion | P11: Riesgo por aparente error en catálogo de Tipo Operación
A12: Adicionales | B12: Tesorería | C12: Eduardo Cabral | D12: 03. DESARROLLO | E12: FILE_CONTRAPARTES | F12: Layout_CONTRAPARTES_v5 -- CONTRAPARTES | G12: Pendiente | H12: Modulo de tesoreria | I12: NTT | K12: DES-Desarrollo Txt | L12: Ext NTT | M12: Int Tesoreria | N12: Tesoreria
A13: Captacion | B13: Operaciones Captacion | C13: Luis Alberto | D13: 03. DESARROLLO | E13: FILE_OCIM_I | F13: Layout OCIM_Diario_V1 -- OCIMN_I - OCIME_I | G13: NA | H13: NA | J13: Estaba identificado con NA | K13: DES-Desarrollo Txt | L13: Ext NTT | M13: Externo | N13: TI
A14: Captacion | B14: Operaciones Captacion | C14: Luis Alberto | D14: 03. DESARROLLO | E14: FILE_OCIM_II | F14: Layout OCIM_II_Activas_V3 -- OCIMN_II - OCIME_II | G14: NA | H14: NA | J14: Estaba identificado con NA | K14: DES-Desarrollo Txt | L14: Ext NTT | M14: Externo | N14: TI
A15: Captacion | B15: Operaciones Captacion | C15: Luis Alberto | D15: 03. DESARROLLO | E15: FILE_SISPAGOS | F15: Layout SISPAGOS BW -- SISPAGOS | G15: Listo | H15: Ntt, ya se reviso txt por usuario VoBo Estructura | I15: Estructura y universo | K15: DES-Desarrollo Txt | L15: Ext NTT | M15: Interno | N15: TI | O15: Se requiera info actualizada congelando sistema para validacion
A16: Captacion | B16: Operaciones Captacion | C16: Luis Alberto | D16: 03. DESARROLLO | E16: FT_TPA | F16: Layout TPA BW_v2 -- TPA | G16: Pendiente | H16: Modulo de tesoreria | I16: Estructura | J16: VoBo sobre estructura | K16: DES-Desarrollo Txt | L16: Ext NTT | M16: Interno | N16: TI
A17: Cartera | B17: Operaciones Credito | C17: Luis Alberto | D17: 03. DESARROLLO | E17: GARANTIA | F17: V1.05_Layouts CREDITO Bancos IFRS (Comercial) (1) | G17: Listo | H17: Se tiene la estructura construida y se integraron los datos con los que se cuenta, aun no se cuenta con todo el universo(Fuentes externas Pantalla comercial) | I17: Estructura | J17: PRELACION_GAR campo pendiente MAPEO | US revisa info restante | K17: DES-Desarrollo Txt | M17: Interno | N17: Riesgos
A18: Cartera | B18: Operaciones Credito | C18: Luis Alberto | D18: 03. DESARROLLO | E18: HIPOTECARIO | F18: V1.05_Layouts CREDITO Bancos IFRS (Hipotecario Simplificado) (1)- HIPOTECARIO | G18: Listo | H18: Se tiene la estructura construida y se integraron los datos con los que se cuenta, aun no se cuenta con todo el universo(Fuentes externas | I18: Estructura | K18: DES-Desarrollo Txt | M18: Interno | N18: TI
A19: Cartera | B19: Operaciones Credito | C19: Luis Alberto | D19: 03. DESARROLLO | E19: LINEA CREDITO | F19: V1.05_Layouts CREDITO Bancos IFRS (Comercial) (1) | G19: Listo | H19: Se tiene la estructura construida y se integraron los datos con los que se cuenta, aun no se cuenta con todo el universo(Fuentes externas Pantalla comercial) | I19: Estructura | K19: DES-Desarrollo Txt | M19: Interno | N19: TI
A20: Cartera | B20: Operaciones Credito | C20: Luis Alberto | D20: 03. DESARROLLO | E20: PAGOS_EXIGIBLES | F20: V1.05_Credito_IFRS9_Consumo_Completo VF (2) | G20: Listo | H20: Se tiene la estructura construida y se integraron los datos con los que se cuenta, aun no se cuenta con todo el universo(Fuentes externas | I20: Estructura | K20: DES-Desarrollo Txt | M20: Interno | N20: TI
A21: Cartera | B21: Operaciones Credito | C21: Luis Alberto | D21: 03. DESARROLLO | E21: PERSONA | F21: V1.05_Layouts CREDITO Bancos IFRS (Comercial) (1) | G21: Listo | H21: Se tiene la estructura construida y se integraron los datos con los que se cuenta, aun no se cuenta con todo el universo(Fuentes externas Pantalla comercial y cualitativa individual) | I21: Estructura | K21: DES-Desarrollo Txt | M21: Interno | N21: TI
A22: Operativos | B22: Operaciones Captacion | C22: Luis Alberto | D22: 03. DESARROLLO | E22: PRODUCTOS CAPTACION CNBV | F22: R2421_Prod Cap -- R2421 | G22: No mapeado | H22: NTT | K22: DES-Desarrollo Txt | L22: Ext NTT | M22: Externo | N22: Operaciones | O22: Este TXT ya fue entregado por NTT el 28/05 y te pase la guía para bajarlo de Transat el 27/10/25. Aún no lo conectan a ATOM.
A23: Cartera | B23: Contabilidad | C23: Ramon Jaimes | D23: 03. DESARROLLO | E23: R04A_MOV_419 | F23: V1.01_Credito_IFRS9_R04A -- A0411 - A0417 - A0419 - A0420 - A0424 - R04A_MOV_419 | G23: Mapeado incompleto | I23: Estructura y universo | J23: Reasignado a Contabilidad | K23: DES-Desarrollo Txt | M23: Interno | N23: Contabilidad
A24: Cartera | B24: Operaciones Credito | C24: Luis Alberto | D24: 03. DESARROLLO | E24: R04A_SALDOS | F24: V1.01_Credito_IFRS9_R04A -- A0411 - A0417 - A0419 - A0420 - A0424 | G24: Listo | H24: Se tiene la estructura construida y se integraron los datos con los que se cuenta, aun no se cuenta con todo el universo(Fuentes externas | I24: Estructura | K24: DES-Desarrollo Txt | M24: Interno | N24: TI
A25: Operativos | B25: Operaciones Captacion | C25: Luis Alberto | D25: 03. DESARROLLO | E25: R2441_42 | F25: Layout R2441_42_V2 --R2441 - R2442 | G25: No mapeado | H25: NTT | K25: DES-Desarrollo Txt | L25: Ext NTT | M25: Externo | N25: Operaciones | O25: Este TXT ya fue entregado por NTT el 16/06 y te pase la guía para bajarlo de Transat el 27/10/25. Aún no lo conectan a ATOM.
A26: Captacion | B26: Producto | C26: Claudia Barroso | D26: 03. DESARROLLO | E26: RECO | F26: Layout RECO BW -- RECO | G26: Listo | H26: Ntt, ya se reviso txt por usuario VoBo | I26: Estructura y universo | J26: Se reasignó a Prodcuto | estaba identificado como VoBo Usuario | K26: DES-Desarrollo Txt | M26: Interno | N26: TI | O26: Se menciona a NTT | P26: Validar la parte de captación NTT para integrar en un solo reporte

Sheet Tesoreria
A1: LAYOUT | B1: REPORTES | C1: AREA | D1: ESTATUS | E1: BLOQUE
A2: CONTRAPARTES | B2: 1 | C2: Tesorería | D2: Mapeo | E2: Operativos | F2: CONTRAPARTES | G2: NTT Responde no lo va a tener | faltan datos de contrapartes | probablemente manual
A3: CVT | B3: 4 | C3: Tesorería | D3: Mapeo | E3: Operativos | F3: MN ME | I3: LAYOUTs | J3: Sts
A4: OFF | B4: 3 | C4: Tesorería | D4: Mapeo | E4: Operativos | I4: Area | J4: Validacion | K4: Mapeo | L4: OK Estructura | M4: Bajaware | N4: En Cero | O4: Total
A5: OPTO | B5: 10 | C5: Tesorería | D5: Mapeo | E5: Operativos | I5: Contabilidad | K5: 1 | O5: 1
A6: REPORTOS | B6: 7 | C6: Tesorería | D6: Mapeo | E6: Operativos | F6: Reportos CDA | I6: Finanzas | J6: 1 | O6: 1
A7: SWAPS | B7: 8 | C7: Tesorería | D7: Mapeo | E7: Operativos | I7: Operaciones - Captacion | L7: 3 | O7: 3
A8: TENENCIA | B8: 2 | C8: Tesorería | D8: Mapeo | E8: Operativos | I8: Riesgos | J8: 2 | K8: 2 | M8: 1 | O8: 5
A9: GARANTÍAS | B9: 4 | C9: Tesorería | D9: Mapeo | E9: Adicionales | I9: Tesorería | K9: 9 | N9: 1 | O9: 10
A10: LID | B10: 1 | C10: Tesorería | D10: Mapeo | E10: Adicionales | I10: Total | J10: 3 | K10: 12 | L10: 3 | M10: 1 | N10: 1 | O10: 20
A11: OCIMN | B11: 3 | C11: Operaciones - Captacion | D11: OK Estructura | E11: Adicionales
A12: ACLME | B12: 5 | C12: Finanzas | D12: Validacion | E12: Adicionales | I12: REPORTES | J12: Sts
A13: ACM | B13: 2 | C13: Contabilidad | D13: Mapeo | E13: Adicionales | I13: Area | J13: Validacion | K13: Mapeo | L13: OK Estructura | M13: Bajaware | N13: En Cero | O13: Total
A14: CRI | B14: 1 | C14: Operaciones - Captacion | D14: OK Estructura | E14: Adicionales | I14: Contabilidad | K14: 2 | O14: 2
A15: FE | B15: 1 | C15: Riesgos | D15: Mapeo | E15: Adicionales | I15: Finanzas | J15: 5 | O15: 5
A16: GL | B16: 6 | C16: Riesgos | D16: Mapeo | E16: Adicionales | I16: Operaciones - Captacion | L16: 5 | O16: 5
A17: ML | B17: 1 | C17: Riesgos | D17: Mapeo | E17: Adicionales | I17: Riesgos | J17: 7 | K17: 2 | M17: 11 | O17: 20
A18: RC'S | B18: 11 | C18: Riesgos | D18: Bajaware | E18: Adicionales | I18: Tesorería | K18: 40 | N18: 2 | O18: 42
A19: XVA | B19: 1 | C19: Riesgos | D19: Mapeo | E19: Adicionales | I19: Total | J19: 12 | K19: 44 | L19: 5 | M19: 11 | N19: 2 | O19: 74
A20: TPA | B20: 1 | C20: Operaciones - Captacion | D20: OK Estructura | E20: Adicionales
A21: R03 | B21: 2 | C21: Tesorería | D21: En Cero | E21: Adicionales | O21: 27
O22: =+O21+GETPIVOTDATA("REPORTES2",$I$12) -> 101
O23: 3
M24: =20*12 -> 240 | O24: =O22*O23 -> 303 | P24: =O24/2 -> 151.5 | Q24: =O24/4 -> 75.75
O25: =O24-M24 -> 63

Sheet Detalle2
A1: Detalles para Rprts - Azure: 03. DESARROLLO
A3: Carpeta | B3: Area | C3: Responsable | D3: Azure | E3: Pestañas | F3: Layout | G3: Estatus | H3: Comentarios | I3: Revision VoBo Usuario | J3: Actualizacion | K3: EstatusAct | L3: Sts2 | M3: Desarrollo | N3: AreaApoyo | O3: Obs Add | P3: Obs Add2 | Q3: NO APLICA | R3: MOTIVO
A4: Cartera | B4: Operaciones Captacion y credito | C4: Luis Alberto | D4: 03. DESARROLLO | E4: CLIENTES_POR_PRODUCTO | F4: R2450_51_52_CLIENTES POR PRODUCTO_V0.5 -- R2450 - R2451 - R2452 (CREDITO) (1) | G4: Listo | H4: Ntt, ya se reviso txt por usuario VoBo | Gris dará aviso a Claudia para su Validación y VoBo | I4: Estructura | K4: DES-Desarrollo Txt | L4: Validar | M4: Interno | N4: TI | O4: 2a vuelta US | P4: Integrar en un layout captación y crédito
A5: Cartera | B5: Operaciones Credito | C5: Luis Alberto | D5: 03. DESARROLLO | E5: CONSUMO | F5: V1.05_Credito_IFRS9_Consumo_Completo VF (2) | G5: Listo | H5: 0212 Confrimar si se puede descargar de ATOM, para avisar a usuario para su validación Se tiene la estructura construida y se integraron los datos con los que se cuenta, aun no se cuenta con todo el universo(Fuentes externas | I5: Estructura | K5: DES-Desarrollo Txt | M5: Interno | N5: TI
A6: Cartera | B6: Operaciones Credito | C6: Luis Alberto | D6: 03. DESARROLLO | E6: CREDITO | F6: V1.05_Layouts CREDITO Bancos IFRS (Comercial) (1) | G6: Listo | H6: 0212 Confrimar si se puede descargar de ATOM, para avisar a usuario para su validación Se tiene la estructura construida y se integraron los datos con los que se cuenta, aun no se cuenta con todo el universo(Fuentes externas | I6: Estructura | K6: DES-Desarrollo Txt | M6: Interno | N6: TI
A7: Operativos | B7: Operaciones Captacion | C7: Luis Alberto | D7: 03. DESARROLLO | E7: TITULARES GARANTIZADOS | F7: R2423_IFRS9_Titulares_Garantizados_V0.4 -- R2423 | G7: No mapeado | H7: 0212 Se debe revisar estatus correcto ya que no se encuentra en Desarrollo NTT | K7: DES-Desarrollo Txt | L7: Ext NTT | M7: Externo | N7: Operaciones
A8: Cartera | B8: Operaciones Credito | C8: Luis Alberto | D8: 03. DESARROLLO | E8: CREDITO_GARANTIA | F8: V1.05_Layouts CREDITO Bancos IFRS (Comercial) (1) | G8: Listo | H8: 0212 Confrimar si se puede descargar de ATOM, para avisar a usuario para su validación Se tiene la estructura construida y se integraron los datos con los que se cuenta, aun no se cuenta con todo el universo(Fuentes externas | I8: Estructura | J8: PORCENTAJE_GARANTIA | Tiene Un campo x validar Riesgos | K8: DES-Desarrollo Txt | M8: Interno | N8: Riesgos
A9: Cartera | B9: Operaciones Credito | C9: Luis Alberto | D9: 03. DESARROLLO | E9: CREDITO_GARANTIA_PERSONAL | F9: V1.05_Layouts CREDITO Bancos IFRS (Comercial) (1) | G9: Listo | H9: 0212 Confrimar si se puede descargar de ATOM, para avisar a usuario para su validación Se tiene la estructura construida y se integraron los datos con los que se cuenta, aun no se cuenta con todo el universo(Fuentes externas | I9: Estructura | J9: PORCENTAJE_GARANTIA_PERS | Tiene Un campo x validar Riesgos | K9: DES-Desarrollo Txt | M9: Interno | N9: Riesgos
A10: Captacion | B10: Operaciones Captacion | C10: Luis Alberto | D10: 03. DESARROLLO | E10: ENT_CAJA_CAPTACION | F10: Layout CCV BW -- CCV | G10: Listo | H10: 0212 Generar la lista de todos los LayOuts que se requiere llenar con información de NTT ( todo lo que se genere NTT del Bucket para asegurar que se tiene contemplado por desarrllo) Ntt, ya se reviso txt por usuario VoBo | I10: Estructura y universo | J10: Validar con usuario si aplican | K10: DES-Desarrollo Txt | L10: Ext NTT | M10: Interno | N10: Operaciones | O10: Se menciona a NTT
A11: Captacion | B11: Operaciones Captacion | C11: Luis Alberto | D11: 03. DESARROLLO | E11: FILE_CAPTACION | F11: Layout Captacion_V3 -- CRI - R08 - OCIM_II | G11: Listo | H11: Ntt, ya se reviso txt por usuario VoBo Estructura (sólo se consume para guardarlos del lado de desarrollo) | ya se encuentran disponibles en ATOM, si son reportes por periodos. | I11: Estructura y universo | J11: 20260108 -- NTT franja fronteriza en cero ION reenvió catalogo | K11: DES-Desarrollo Txt | L11: Ext NTT | M11: Interno | N11: TI | O11: Se requiera info actualizada congelando sistema para validacion | P11: Riesgo por aparente error en catálogo de Tipo Operación
A12: Adicionales | B12: Tesorería | C12: Eduardo Cabral | D12: 03. DESARROLLO | E12: FILE_CONTRAPARTES | F12: Layout_CONTRAPARTES_v5 -- CONTRAPARTES | G12: Pendiente | H12: Modulo de tesoreria | Se requiere terminar ciclo completo para Usuario pueda realizar las pruebas | I12: NTT | K12: DES-Desarrollo Txt | L12: Ext NTT | M12: Int Tesoreria | N12: Tesoreria
A13: Captacion | B13: Operaciones Captacion | C13: Luis Alberto | D13: 03. DESARROLLO | E13: FILE_OCIM_I | F13: Layout OCIM_Diario_V1 -- OCIMN_I - OCIME_I | G13: Vacío | H13: Gris compartirá LayOut para que se genere la estructura | J13: Estaba identificado con NA | K13: DES-Desarrollo Txt | L13: Ext NTT | M13: Externo | N13: TI
A14: Captacion | B14: Operaciones Captacion | C14: Luis Alberto | D14: 03. DESARROLLO | E14: FILE_OCIM_II | F14: Layout OCIM_II_Activas_V3 -- OCIMN_II - OCIME_II | G14: Vacío | H14: Gris compartirá LayOut para que se genere la estructura | J14: Estaba identificado con NA | K14: DES-Desarrollo Txt | L14: Ext NTT | M14: Externo | N14: TI
A15: Captacion | B15: Operaciones Captacion | C15: Luis Alberto | D15: 03. DESARROLLO | E15: FILE_SISPAGOS | F15: Layout SISPAGOS BW -- SISPAGOS | G15: Listo | H15: Ntt, ya se reviso txt por usuario VoBo Estructura (sólo se consume para guardarlos del lado de desarrollo) | ya se encuentran disponibles en ATOM, si son reportes por periodos. | I15: Estructura y universo | K15: DES-Desarrollo Txt | L15: Ext NTT | M15: Interno | N15: TI | O15: Se requiera info actualizada congelando sistema para validacion
A16: Captacion | B16: Operaciones Captacion | C16: Luis Alberto | D16: 03. DESARROLLO | E16: FT_TPA | F16: Layout TPA BW_v2 -- TPA | G16: Pendiente | H16: Modulo de tesoreria | Gris deberá compartir LayOut a Desarrollo | I16: Estructura | J16: VoBo sobre estructura | K16: DES-Desarrollo Txt | L16: Ext NTT | M16: Interno | N16: TI
A17: Cartera | B17: Operaciones Credito | C17: Luis Alberto | D17: 03. DESARROLLO | E17: GARANTIA | F17: V1.05_Layouts CREDITO Bancos IFRS (Comercial) (1) | G17: Listo | H17: 0212 Se debe vaidar de que fecha se puede hacer la prueba de extración área de Desarrollo | 0213 Se tiene la estructura construida y se integraron los datos con los que se cuenta, aun no se cuenta con todo el universo(Fuentes externas Pantalla comercial) | I17: Estructura | J17: PRELACION_GAR campo pendiente MAPEO | US revisa info restante | K17: DES-Desarrollo Txt | M17: Interno | N17: Riesgos
A18: Cartera | B18: Operaciones Credito | C18: Luis Alberto | D18: 03. DESARROLLO | E18: HIPOTECARIO | F18: V1.05_Layouts CREDITO Bancos IFRS (Hipotecario Simplificado) (1)- HIPOTECARIO | G18: Listo | H18: 0212 Se tiene la estructura construida y se integraron los datos con los que se cuenta, aun no se cuenta con todo el universo(Fuentes externas | I18: Estructura | K18: DES-Desarrollo Txt | M18: Interno | N18: TI
A19: Cartera | B19: Operaciones Credito | C19: Luis Alberto | D19: 03. DESARROLLO | E19: LINEA CREDITO | F19: V1.05_Layouts CREDITO Bancos IFRS (Comercial) (1) | G19: Listo | H19: 0212 Se debe vaidar de que fecha se puede hacer la prueba de extración área de Desarrollo | 0213 Se tiene la estructura construida y se integraron los datos con los que se cuenta, aun no se cuenta con todo el universo(Fuentes externas Pantalla comercial) | I19: Estructura | K19: DES-Desarrollo Txt | M19: Interno | N19: TI
A20: Cartera | B20: Operaciones Credito | C20: Luis Alberto | D20: 03. DESARROLLO | E20: PAGOS_EXIGIBLES | F20: V1.05_Credito_IFRS9_Consumo_Completo VF (2) | G20: Listo | H20: 0212 Confrimar si se puede descargar de ATOM, para avisar a usuario para su validación Se tiene la estructura construida y se integraron los datos con los que se cuenta, aun no se cuenta con todo el universo(Fuentes externas | I20: Estructura | K20: DES-Desarrollo Txt | M20: Interno | N20: TI
A21: Cartera | B21: Operaciones Credito | C21: Luis Alberto | D21: 03. DESARROLLO | E21: PERSONA | F21: V1.05_Layouts CREDITO Bancos IFRS (Comercial) (1) | G21: Listo | H21: 0212 Se debe vaidar de que fecha se puede hacer la prueba de extración área de Desarrollo | 0213 Se tiene la estructura construida y se integraron los datos con los que se cuenta, aun no se cuenta con todo el universo(Fuentes externas Pantalla comercial y cualitativa) | I21: Estructura | K21: DES-Desarrollo Txt | M21: Interno | N21: TI
A22: Operativos | B22: Operaciones Captacion | C22: Luis Alberto | D22: 03. DESARROLLO | E22: PRODUCTOS CAPTACION CNBV | F22: R2421_Prod Cap -- R2421 | G22: No mapeado | H22: 0212 Gris, Revisar con Jenny si NTT ya lo tiene Mapeado NTT | K22: DES-Desarrollo Txt | L22: Ext NTT | M22: Externo | N22: Operaciones | O22: Este TXT ya fue entregado por NTT el 28/05 y te pase la guía para bajarlo de Transat el 27/10/25. Aún no lo conectan a ATOM.
A23: Cartera | B23: Contabilidad | C23: Ramon Jaimes | D23: 03. DESARROLLO | E23: R04A_MOV_419 | F23: V1.01_Credito_IFRS9_R04A -- A0411 - A0417 - A0419 - A0420 - A0424 - R04A_MOV_419 | G23: Mapeado incompleto | H23: 0212 Gris Revisar las notas de Martín para trazabilidad o darselo a Ramón para complemento de Mapeo | Carlo me envía correo de lo que se tiene documentado | I23: Estructura y universo | J23: Reasignado a Contabilidad | K23: DES-Desarrollo Txt | M23: Interno | N23: Contabilidad
A24: Cartera | B24: Operaciones Credito | C24: Luis Alberto | D24: 03. DESARROLLO | E24: R04A_SALDOS | F24: V1.01_Credito_IFRS9_R04A -- A0411 - A0417 - A0419 - A0420 - A0424 | G24: Listo | H24: 0212 Confrimar si se puede descargar de ATOM, para avisar a usuario para su validación Se tiene la estructura construida y se integraron los datos con los que se cuenta, aun no se cuenta con todo el universo (Fuentes externas | I24: Estructura | K24: DES-Desarrollo Txt | M24: Interno | N24: TI
A25: Operativos | B25: Operaciones Captacion | C25: Luis Alberto | D25: 03. DESARROLLO | E25: R2441_42 | F25: Layout R2441_42_V2 --R2441 - R2442 | G25: No mapeado | H25: 0212 Gris, Revisar con Jenny si NTT ya lo tiene Mapeado NTT | K25: DES-Desarrollo Txt | L25: Ext NTT | M25: Externo | N25: Operaciones | O25: Este TXT ya fue entregado por NTT el 16/06 y te pase la guía para bajarlo de Transat el 27/10/25. Aún no lo conectan a ATOM.
A26: Captacion | B26: Producto | C26: Claudia Barroso | D26: 03. DESARROLLO | E26: RECO | F26: Layout RECO BW -- RECO | G26: Listo | H26: Ntt, ya se reviso txt por usuario VoBo la parte de NTT | el complemento interno se Desarrollo trabajará para concluirlo | Deadline ? | Gris asigna tarea en Azure para complementar el LayOut con información de excel proporcionada por Usuario (Claudia) | I26: Estructura y universo | J26: Se reasignó a Prodcuto | estaba identificado como VoBo Usuario | K26: DES-Desarrollo Txt | M26: Interno | N26: TI | O26: Se menciona a NTT | P26: Validar la parte de captación NTT para integrar en un solo reporte

Sheet Detalle3
A1: Detalles de Rprts - Azure: 02. MAPEO
A3: Carpeta | B3: Area | C3: Responsable | D3: Azure | E3: Pestañas | F3: Layout | G3: Estatus | H3: Comentarios | I3: Revision VoBo Usuario | J3: Actualizacion | K3: EstatusAct | L3: Sts2 | M3: Desarrollo | N3: AreaApoyo | O3: Obs Add | P3: Obs Add2 | Q3: NO APLICA | R3: MOTIVO
A4: Adicionales | B4: Tesorería | C4: Eduardo Cabral | D4: 02. MAPEO | E4: VENC_ANT_REPORTOS | F4: Layout_REPORTOS_MN_ME_V7_2024 -- REPORTOS | G4: Pendiente | H4: Modulo de tesoreria | I4: NTT | K4: US-Mapeo | L4: Ext NTT | M4: Int Tesoreria | N4: Tesoreria | O4: Layout_REPORTOS_MN_ME_V7 -- REPORTOS | P4: modif nomb layout
A5: Adicionales | B5: Captacion | C5: Arturo Angeles | D5: 02. MAPEO | E5: USUARIOS NO CLIENTES BE | F5: R1522_USUARIOS NO CLIENTES BE_V0.4 -- R15 1522 | G5: No mapeado | K5: US-Mapeo | M5: Interno | N5: Finanzas
A6: Adicionales | B6: Tesorería | C6: Eduardo Cabral | D6: 02. MAPEO | E6: LAYOUT Seccion A Cat Lineas | F6: LAYOUT LID V4 | H6: Reporte habilitado en 2025 no contemplado en scope original | I6: Estructura y universo | K6: US-Mapeo | L6: Ext NTT | M6: Int Tesoreria Add | N6: Tesoreria
A7: Adicionales | B7: Tesorería | C7: Eduardo Cabral | D7: 02. MAPEO | E7: LAYOUT Seccion 5 Lineas de Cre | F7: LAYOUT LID V4 | H7: Reporte habilitado en 2025 no contemplado en scope original | I7: Estructura y universo | K7: US-Mapeo | L7: Ext NTT | M7: Int Tesoreria Add | N7: Tesoreria
A8: Adicionales | B8: Tesorería | C8: Eduardo Cabral | D8: 02. MAPEO | E8: LAYOUT LID CORRESPONSALES | F8: LAYOUT LID V4 | H8: Reporte habilitado en 2025 no contemplado en scope original | I8: Estructura y universo | K8: US-Mapeo | L8: Ext NTT | M8: Int Tesoreria Add | N8: Tesoreria
A9: Adicionales | B9: Tesorería | C9: Eduardo Cabral | D9: 02. MAPEO | E9: LAYOUT LID LIQUIDACIONES | F9: LAYOUT LID V4 | H9: Reporte habilitado en 2025 no contemplado en scope original | I9: Estructura y universo | K9: US-Mapeo | L9: Ext NTT | M9: Int Tesoreria Add | N9: Tesoreria
A10: Adicionales | B10: Tesorería | C10: Eduardo Cabral | D10: 02. MAPEO | E10: SWAPS | F10: Layout_SWAPS_V9 -- SWAPS | G10: Pendiente | H10: Modulo de tesoreria | I10: NTT | K10: US-Mapeo | L10: Ext NTT | M10: Int Tesoreria | N10: Tesoreria | O10: Layout_SWAPS_V9.1 -- SWAPS | P10: modif nomb layout
A11: Adicionales | B11: Tesorería | C11: Eduardo Cabral | D11: 02. MAPEO | E11: LAYOUT Seccion 1 LDID | F11: LAYOUT LID V4 | H11: Reporte habilitado en 2025 no contemplado en scope original | I11: Estructura y universo | K11: US-Mapeo | L11: Ext NTT | M11: Int Tesoreria Add | N11: Tesoreria
A12: Adicionales | B12: Tesorería | C12: Eduardo Cabral | D12: 02. MAPEO | E12: SWAP_IV_COM | F12: Layout_SWAPS_V9 -- SWAPS | G12: Pendiente | H12: Modulo de tesoreria | I12: NTT | K12: US-Mapeo | L12: Ext NTT | M12: Int Tesoreria | N12: Tesoreria | O12: Layout_SWAPS_V9.1 -- SWAPS | P12: modif nomb layout | Q12: Alex valida con Eduardo
A13: Adicionales | B13: Tesorería | C13: Eduardo Cabral | D13: 02. MAPEO | E13: SWAP_IV | F13: Layout_SWAPS_V9 -- SWAPS | G13: Pendiente | H13: Modulo de tesoreria | I13: NTT | K13: US-Mapeo | L13: Ext NTT | M13: Int Tesoreria | N13: Tesoreria | O13: Layout_SWAPS_V9.1 -- SWAPS | P13: modif nomb layout | Q13: Alex valida con Eduardo
A14: Situacion Finaciera | B14: Contabilidad | C14: Ramon Jaimes | D14: 02. MAPEO | E14: ACM II_ADIC | F14: LAYOUT_ACM_II V0.1 -- R01 | G14: Listo | H14: Revision de txt por parte del usuario | I14: Estructura y universo | J14: Info de credito enviada para Vobo, falta Mapeo Info Tesoreria | K14: US-Mapeo | M14: Interno | N14: Contabilidad
A15: Adicionales | B15: Tesorería | C15: Eduardo Cabral | D15: 02. MAPEO | E15: SWAP_FLUJOS | F15: Layout_SWAPS_V9 -- SWAPS | G15: Pendiente | H15: Modulo de tesoreria | I15: NTT | K15: US-Mapeo | L15: Ext NTT | M15: Int Tesoreria | N15: Tesoreria | O15: Layout_SWAPS_V9.1 -- SWAPS | P15: modif nomb layout
A16: Adicionales | B16: Tesorería | C16: Eduardo Cabral | D16: 02. MAPEO | E16: SWAP_CUOTAS_INT | F16: Layout_SWAPS_V9 -- SWAPS | G16: Pendiente | H16: Modulo de tesoreria | I16: NTT | K16: US-Mapeo | L16: Ext NTT | M16: Int Tesoreria | N16: Tesoreria | O16: Layout_SWAPS_V9.1 -- SWAPS | P16: modif nomb layout
A17: Adicionales | B17: Tesorería | C17: Eduardo Cabral | D17: 02. MAPEO | E17: SWAP_CONVO | F17: Layout_SWAPS_V9 -- SWAPS | G17: Pendiente | H17: Modulo de tesoreria | I17: NTT | K17: US-Mapeo | L17: Ext NTT | M17: Int Tesoreria | N17: Tesoreria | O17: Layout_SWAPS_V9.1 -- SWAPS | P17: modif nomb layout
A18: Situacion Finaciera | B18: Contabilidad | C18: Ramon Jaimes | D18: 02. MAPEO | E18: ACM II-Mapeo | F18: LAYOUT_ACM_II V0.1 -- R01 | G18: Listo | H18: Revision de txt por parte del usuario | I18: Estructura y universo | J18: Info de credito enviada para Vobo, falta Mapeo Info Tesoreria | K18: US-Mapeo | M18: Interno | N18: Contabilidad
A19: Adicionales | B19: Tesorería | C19: Eduardo Cabral | D19: 02. MAPEO | E19: CANASTA_REPORTOS | F19: Layout_REPORTOS_MN_ME_V7_2024 -- REPORTOS | G19: Pendiente | H19: Modulo de tesoreria | I19: NTT | K19: US-Mapeo | L19: Ext NTT | M19: Int Tesoreria | N19: Tesoreria | O19: Layout_REPORTOS_MN_ME_V7 -- REPORTOS | P19: modif nomb layout
A20: Riesgos | B20: Riesgos | C20: Homero Sanchez | D20: 02. MAPEO | E20: CARGA INICIAL IN-MIN | F20: LAYOUT CARGA INICIAL IN_MIN - Calculo Riesgo Operacional | G20: No mapeado | H20: Se reliza una solo carga, indica el usuario se debe relizar hasta la ejecucion con Bajware | J20: Reporte inicial Riesgos integrará 36 meses al momento de reporte | K20: US-Mapeo | L20: Validar | M20: Interno | N20: Riesgos | O20: x | P20: no se necesita mapeo Riesgos emite info completa -- Historico una sola carga, depende funcionalidad al 100. promedio movil | ingresos netos sin dependencias
A21: Riesgos | B21: Riesgos | C21: Homero Sanchez | D21: 02. MAPEO | E21: CARGA INICIAL PI-MIN | F21: LAYOUT CARGA INICIAL PI_MIN - Calculo Riesgo Operacional | G21: No mapeado | H21: Se reliza una solo carga, indica el usuario se debe relizar hasta la ejecucion con Bajware | J21: Reporte inicial Riesgos integrará 36 meses al momento de reporte | K21: US-Mapeo | L21: Validar | M21: Interno | N21: Riesgos | O21: Dep otra Area | P21: dependencia con Conta | perdidas operativas revisa Riesgos/Contabilidad
A22: Liquidez | B22: Tesorería | C22: Eduardo Cabral | D22: 02. MAPEO | E22: CF_ESP | F22: Layout CF_V3 | G22: Pendiente | H22: Modulo de tesoreria | I22: NTT | J22: ** Nota: Bajaware incluye el Layout de CF Concentración de Fondeo y ya no existe en el portal de Banxico, favor de confirmar con ellos, era un reporte semanal y mensual que combina Captación Tradicional e Interbancaria, similar al CRI ** | K22: US-Mapeo | L22: Ext NTT | M22: Int Tesoreria | N22: Tesoreria | O22: Confirma Bajaware que se continua vigente la secc 1 | P22: Cambio Nombre pestaña | Q22: xxx Validar con Captación
A23: Situacion Finaciera | B23: Contabilidad | C23: Ramon Jaimes | D23: 02. MAPEO | E23: ENT_CUOTAS_IPAB_DEF | F23: Layout IPAB_V3 - IPAB | G23: Por iniciar | H23: Se requiere recepcion de requerimiento y Excel. (Usuario) | I23: Estructura y universo | K23: US-Mapeo | M23: Interno | N23: Contabilidad
A24: Adicionales | B24: Finanzas | C24: Arturo Angeles | D24: 02. MAPEO | E24: FILE_ACLME | F24: Layout_ACLME_SECCION_I_V_v3 -- ACLME | G24: Pendiente | H24: Modulo de tesoreria | I24: NTT | K24: US-Mapeo | L24: Ext NTT | M24: Int Tesoreria Add | N24: Finanzas
A25: Adicionales | B25: Finanzas | C25: Arturo Angeles | D25: 02. MAPEO | E25: FILE_ACLME_AJUSTES_DDMMAA | F25: ACLME_Ajustes_V3 -- ACLME | G25: Pendiente | H25: Modulo de tesoreria | I25: NTT | K25: US-Mapeo | L25: Ext NTT | M25: Int Tesoreria Add | N25: Finanzas
A26: Adicionales | B26: Tesorería | C26: Eduardo Cabral | D26: 02. MAPEO | E26: REPORTOS_MNME | F26: Layout_REPORTOS_MN_ME_V7_2024 -- REPORTOS | G26: Pendiente | H26: Modulo de tesoreria | I26: NTT | K26: US-Mapeo | L26: Ext NTT | M26: Int Tesoreria | N26: Tesoreria | O26: Layout_REPORTOS_MN_ME_V7 -- REPORTOS | P26: modif nomb layout
A27: Adicionales | B27: Finanzas | C27: Arturo Angeles | D27: 02. MAPEO | E27: FILE_ACLME_CONCEPTOSFIJOS_DDMMAA | F27: Layout_ACLME_ConceptosFijos_v3 -- ACLME | G27: Pendiente | H27: Modulo de tesoreria | I27: NTT | K27: US-Mapeo | L27: Ext NTT | M27: Int Tesoreria Add | N27: Finanzas
A28: Adicionales | B28: Riesgos | C28: Homero Sanchez | D28: 02. MAPEO | E28: FILE_CFEN | F28: LAYOUT CFEN-3 | G28: No mapeado | H28: Se esta relizando ampeado por parte del usuario | I28: Estructura y universo | J28: Falta info de Contabilidad Anexo 1 O | K28: US-Mapeo | M28: Int Tesoreria Add | N28: Tesoreria/Contabilidad | O28: Dep otra Area
A29: Mercados | B29: Tesorería | C29: Eduardo Cabral | D29: 02. MAPEO | E29: FILE_CVT_TRP | F29: Layout_CVT_TRP_V2 | G29: Pendiente | H29: Modulo de tesoreria | I29: NTT | K29: US-Mapeo | L29: Ext NTT | M29: Int Tesoreria | N29: Tesoreria
A30: Adicionales | B30: Tesorería | C30: Eduardo Cabral | D30: 02. MAPEO | E30: FILE_FUT_CONVAL | F30: Layout OFF_FX_V7 -- OFF | G30: Pendiente | H30: Modulo de tesoreria | I30: NTT | K30: US-Mapeo | L30: Ext NTT | M30: Int Tesoreria | N30: Tesoreria
A31: Adicionales | B31: Tesorería | C31: Eduardo Cabral | D31: 02. MAPEO | E31: FILE_GARANTIAS_II | F31: Layout_Garantias_V1 - GARANTIAS | G31: Pendiente | H31: Modulo de tesoreria | I31: NTT | J31: No es Scope iniical RMC, asignado a Tesoreria | K31: US-Mapeo | L31: Ext NTT | M31: Int Tesoreria Add | N31: Tesoreria
A32: Adicionales | B32: UNE | C32: Martin Roman | D32: 02. MAPEO | E32: RECLAMACIONES | F32: LAYOUT R27_V1 -- R27 - 2701 | G32: No mapeado | K32: US-Mapeo | M32: Interno | N32: UNE
A33: Adicionales | B33: Tesorería | C33: Eduardo Cabral | D33: 02. MAPEO | E33: FILE_GARANTIAS_IV | F33: Layout_Garantias_V1 - GARANTIAS | G33: Pendiente | H33: Modulo de tesoreria | I33: NTT | J33: No es Scope iniical RMC, asignado a Tesoreria | K33: US-Mapeo | L33: Ext NTT | M33: Int Tesoreria Add | N33: Tesoreria
A34: Adicionales | B34: Riesgos | C34: Homero Sanchez | D34: 02. MAPEO | E34: R35_1 | F34: Layout R35_1 -- R35 | G34: No mapeado | H34: Se tiene que realizar una vez migrado a Banco | se puede mapear la cartera de creditos -- Riesgos / Exp Valores Transac -- Tesoreria | I34: Estructura y universo | K34: US-Mapeo | M34: Interno | N34: Riesgos
A35: Liquidez | B35: Riesgos | C35: Homero Sanchez | D35: 02. MAPEO | E35: FILE_ML | F35: Layout ML-4 -- ML | G35: Pendiente | H35: Modulo de tesoreria | I35: NTT | K35: US-Mapeo | L35: Ext NTT | M35: Int Tesoreria Add | N35: Riesgos
A36: Adicionales | B36: Tesorería | C36: Eduardo Cabral | D36: 02. MAPEO | E36: FILE_OFF_CONVAL | F36: Layout OFF_FX_V7 -- OFF | G36: Pendiente | H36: Modulo de tesoreria | I36: NTT | K36: US-Mapeo | L36: Ext NTT | M36: Int Tesoreria | N36: Tesoreria
A37: Adicionales | B37: Tesorería | C37: Eduardo Cabral | D37: 02. MAPEO | E37: FILE_OFF_FX_DDMMAA | F37: Layout OFF_FX_V7 -- OFF | G37: Pendiente | H37: Modulo de tesoreria | I37: NTT | K37: US-Mapeo | L37: Ext NTT | M37: Int Tesoreria | N37: Tesoreria
A38: Adicionales | B38: Tesorería | C38: Eduardo Cabral | D38: 02. MAPEO | E38: FILE_OPTO_CONVO | F38: Layout_OPTO_V3 -- OPTO | G38: Pendiente | H38: Modulo de tesoreria | I38: NTT | K38: US-Mapeo | L38: Ext NTT | M38: Int Tesoreria | N38: Tesoreria | Q38: Alex valida con Eduardo | R38: puede que no se opere como covertura
A39: Adicionales | B39: Tesorería | C39: Eduardo Cabral | D39: 02. MAPEO | E39: FILE_OPTO_II | F39: Layout_OPTO_V3 -- OPTO | G39: Pendiente | H39: Modulo de tesoreria | I39: NTT | K39: US-Mapeo | L39: Ext NTT | M39: Int Tesoreria | N39: Tesoreria
A40: Operativos | B40: Operaciones Captacion | C40: Arturo Angeles | D40: 02. MAPEO | E40: R2431 | F40: Layout R2431_V4 -- R24 C2431 | G40: No mapeado | H40: NTT | J40: • El 18/12/24 le indicamos al PMO que este Layout no correspondía a Operaciones. • Nuevamente en la reunión del 23/07/25 volvimos a pedir que lo asignaran y el acuerdo fue el siguiente: "Contabilidad se lleva a revisar el Layout y si hacen faltan campos se investiga lo que hace falta. Tanto crédito como captación", Sharon le iba a dar seguimiento. • Es urgente que lo asignen, anexo minuta del 23/07/25. | K40: US-Mapeo | L40: Ext NTT | M40: Externo | N40: Finanzas | O40: Asignado a Captación | P40: El Layout R24 Serie C, no le corresponde a Operaciones, solicita información de partes relacionadas que nosotros no tenemos, favor de revisar a fondo y determinar qué área lo debe llenar.
A41: Mercados | B41: Tesorería | C41: Eduardo Cabral | D41: 02. MAPEO | E41: FILE_TENENCIA_PRECIO | F41: CORE_LayoutTenenciaAdicional_v3.2 -- TENENCIA | G41: Pendiente | H41: Modulo de tesoreria | I41: NTT | K41: US-Mapeo | L41: Ext NTT | M41: Int Tesoreria | N41: Tesoreria
...

Sheet PRESENTACION
A1: Desarrollo | B1: (Varios elementos)
E2: AZURE
A3: Etiquetas de fila | B3: Cuenta de Carpeta
A4: CERRADA | B4: 12 | C4: RCS QUE SI DEBEMOS ENVIAR | E4: 7
A5: 02. MAPEO | B5: 49 | E5: 67
A6: 03. DESARROLLO | B6: 23 | C6: INCLUYE LOS DE NTT | E6: 20
A7: 05. VOBO US | B7: 58 | E7: 2
A8: 06. BW-EJECUCION | B8: 8 | E8: 54
A9: 01. ASIGNA | B9: 6 | C9: LO TRABAJA BAJAWARE
A10: 04. VALIDA US | B10: 1 | H10: ASIGNACION AREA
A11: Total general | B11: 157 | H11: MAPEO
A12: VOBO US BW | H12: DESARROLLO
H13: VALIDACION
H14: VO BO USUARIO
B15: =SUM(B4:B8) -> 150 | C15: SIN TOMAR ENCUENTA BAJAWARE
B16: =GETPIVOTDATA("Carpeta",$A$3,"Azure","VOBO DE USUARIO A LAYOUT GENERADO")/B15 -> #REF!
C21: Val | D21: AreaApoyo
C22: Rprts | M22: Porc | W22: Total Rprts | X22: Total Porc
A23: Azure | B23: EstatusAct | C23: BajaWare | D23: Contabilidad | E23: Finanzas | F23: Operaciones | G23: Producto | H23: Riesgos | I23: Tesoreria | J23: Tesoreria/Contabilidad | K23: TI | L23: UNE | M23: BajaWare | N23: Contabilidad | O23: Finanzas | P23: Operaciones | Q23: Producto | R23: Riesgos | S23: Tesoreria | T23: Tesoreria/Contabilidad | U23: TI | V23: UNE
A24: 02. MAPEO | B24: US-Mapeo | D24: 4 | E24: 8 | H24: 4 | I24: 31 | J24: 1 | L24: 1 | M24: 0 | N24: 0.027586207 | O24: 0.055172414 | P24: 0 | Q24: 0 | R24: 0.027586207 | S24: 0.2137931 | T24: 0.0068965517 | U24: 0 | V24: 0.0068965517 | W24: 49 | X24: 0.33793103
A25: 03. DESARROLLO | B25: DES-Desarrollo Txt | D25: 1 | F25: 4 | H25: 3 | I25: 1 | K25: 14 | M25: 0 | N25: 0.0068965517 | O25: 0 | P25: 0.027586207 | Q25: 0 | R25: 0.020689655 | S25: 0.0068965517 | T25: 0 | U25: 0.096551724 | V25: 0 | W25: 23 | X25: 0.15862069
A26: 05. VOBO US | B26: US-VoBo | D26: 10 | G26: 42 | H26: 6 | M26: 0 | N26: 0.068965517 | O26: 0 | P26: 0 | Q26: 0.28965517 | R26: 0.04137931 | S26: 0 | T26: 0 | U26: 0 | V26: 0 | W26: 58 | X26: 0.4
A27: 06. BW-EJECUCION | B27: BW-Ejecucion | C27: 8 | M27: 0.055172414 | N27: 0 | O27: 0 | P27: 0 | Q27: 0 | R27: 0 | S27: 0 | T27: 0 | U27: 0 | V27: 0 | W27: 8 | X27: 0.055172414
A28: 01. ASIGNA | B28: Valida Areas | H28: 6 | M28: 0 | N28: 0 | O28: 0 | P28: 0 | Q28: 0 | R28: 0.04137931 | S28: 0 | T28: 0 | U28: 0 | V28: 0 | W28: 6 | X28: 0.04137931
A29: 04. VALIDA US | B29: US-Validación Txt | D29: 1 | M29: 0 | N29: 0.0068965517 | O29: 0 | P29: 0 | Q29: 0 | R29: 0 | S29: 0 | T29: 0 | U29: 0 | V29: 0 | W29: 1 | X29: 0.0068965517
A30: Total | C30: 8 | D30: 16 | E30: 8 | F30: 4 | G30: 42 | H30: 19 | I30: 32 | J30: 1 | K30: 14 | L30: 1 | M30: 0.055172414 | N30: 0.11034483 | O30: 0.055172414 | P30: 0.027586207 | Q30: 0.28965517 | R30: 0.13103448 | S30: 0.22068966 | T30: 0.0068965517 | U30: 0.096551724 | V30: 0.0068965517 | W30: 145 | X30: 1
C33: Val
A34: Azure | B34: EstatusAct | C34: Rprts | D34: Porc
A35: 01. ASIGNA | B35: Valida Areas | C35: 6 | D35: 0.04137931
A36: 02. MAPEO | C36: 49 | D36: 0.33793103
A37: 03. DESARROLLO | C37: 23 | D37: 0.15862069
A38: 04. VALIDA US | B38: US-Validación Txt | C38: 1 | D38: 0.0068965517
A39: 05. VOBO US | B39: US-VoBo | C39: 58 | D39: 0.4
A40: 06. BW-EJECUCION | B40: BW-Ejecucion | C40: 8 | D40: 0.055172414
A41: Total | C41: 145 | D41: 1
C43: 27 | D43: envío vacios
C44: 29 | D44: na aplica
C46: =SUM(C41:C44) -> 201
C48: 195
C49: =C46-C48 -> 6

Sheet Resumen Original
H1: Desarrollo | I1: Interno
H3: Distribución | J3: EstatusAct
H4: Responsable | I4: Area | J4: Backlog | K4: Mapeo Usuario | L4: Txt en Desarrollo | M4: Validacion Txt Usuario | N4: VoBo Usuario | O4: Total | P4: % Avance | Q4: % Total
B5: Area | C5: Desarrollo | H5: Claudia Barroso | I5: Producto | L5: 1 | N5: 42 | O5: 43 | P5: =N5/O5 -> 0.97674419 | Q5: =O5/$O$13 -> 21.5
B6: Estatus | C6: Interno | D6: Externo | E6: NA | F6: Total | H6: Eduardo Cabral | I6: Tesorería | L6: 1 | O6: 1 | P6: =N6/O6 -> 0 | Q6: =O6/$O$13 -> 0.5
B7: Contabilidad | C7: 14 | F7: 14 | H7: Homero Sanchez | I7: Riesgos | J7: 2 | K7: 1 | N7: 5 | O7: 8 | P7: =N7/O7 -> 0.625 | Q7: =O7/$O$13 -> 4
B8: Mapeo Usuario | C8: 4 | F8: 4 | H8: Luis Alberto | I8: Operaciones Captacion | L8: 2 | N8: 1 | O8: 3 | P8: =N8/O8 -> 0.33333333 | Q8: =O8/$O$13 -> 1.5
B9: Validacion Txt Usuario | C9: 4 | F9: 4 | I9: Operaciones Captacion y credito | K9: 1 | L9: 1 | O9: 2 | P9: =N9/O9 -> 0 | Q9: =O9/$O$13 -> 1
B10: VoBo Usuario | C10: 4 | F10: 4 | I10: Operaciones Credito | L10: 7 | M10: 3 | O10: 10 | P10: =N10/O10 -> 0 | Q10: =O10/$O$13 -> 5
B11: Txt en Desarrollo | C11: 2 | F11: 2 | H11: Ramon Jaimes | I11: Contabilidad | K11: 2 | M11: 5 | N11: 8 | O11: 15 | P11: =N11/O11 -> 0.53333333 | Q11: =O11/$O$13 -> 7.5
B12: Operaciones Captacion | C12: 4 | D12: 13 | E12: 7 | F12: 24 | H12: Martin Roman | I12: UNE | K12: 1 | O12: 1 | P12: =N12/O12 -> 0 | Q12: =O12/$O$13 -> 0.5
B13: Backlog | D13: 13 | E13: 7 | F13: 20 | H13: Arturo Angeles | I13: Producto | K13: 2 | O13: 2 | P13: =N13/O13 -> 0 | Q13: =SUM(Q5:Q12) -> 41.5
B14: VoBo Usuario | C14: 4 | F14: 4 | H14: Total | J14: 2 | K14: 7 | L14: 12 | M14: 8 | N14: 56 | O14: 85
B15: Operaciones Captacion y credito | C15: 3 | F15: 3 | Q15: =SUM(J15:P15) -> 0
B16: Mapeo Usuario | C16: 2 | F16: 2
B17: Validacion Txt Usuario | C17: 1 | F17: 1
B18: Operaciones Credito | C18: 10 | E18: 6 | F18: 16
B19: Backlog | E19: 6 | F19: 6
B20: Validacion Txt Usuario | C20: 3 | F20: 3
B21: Txt en Desarrollo | C21: 7 | F21: 7
B22: Producto | C22: 7 | E22: 12 | F22: 19
B23: Backlog | E23: 12 | F23: 12
B24: Mapeo Usuario | C24: 2 | F24: 2
B25: VoBo Usuario | C25: 5 | F25: 5
B26: Riesgos | C26: 9 | D26: 12 | F26: 21
B27: Backlog | C27: 2 | D27: 12 | F27: 14
B28: Mapeo Usuario | C28: 2 | F28: 2
B29: Txt en Desarrollo | C29: 5 | F29: 5
B30: Riesgos y tesoreria | D30: 2 | F30: 2
B31: Backlog | D31: 2 | F31: 2
B32: Tesorería | D32: 58 | F32: 58
B33: Backlog | D33: 58 | F33: 58
B34: TBD | C34: 1 | F34: 1
B35: Mapeo Usuario | C35: 1 | F35: 1
B36: Total | C36: 48 | D36: 85 | E36: 25 | F36: 158

Sheet PendContab20260120
B3: Detalles para NumReportes - AreaApoyo: Contabilidad, EstatusAct: US-Validación Txt
B5: Pestañas | C5: Layout | D5: Actualizacion | E5: EstatusAct | F5: Entrega
B6: CATALOGO MINIMO | C6: R01_Catalogo Minimo --R01 - R10 - R12 - R13 | D6: Archivo Txt enviado, comentarios pendientes | E6: US-Validación Txt | F6: miercoles 28
B7: ACM II_ADIC | C7: LAYOUT_ACM_II V0.1 -- R01 | D7: Archivo TXT de Credito enviado, comentarios pendientes Mapeo pendiente cuentas Tesorería | E7: US-Mapeo | F7: lunes 26 rev
B8: ACM II-Mapeo | C8: LAYOUT_ACM_II V0.1 -- R01
B9: ENT_CUOTAS_IPAB_DEF | C9: Layout IPAB_V3 - IPAB | D9: Mapeo Pendiente | F9: viernes 30
B10: R04A_MOV_419 | C10: V1.01_Credito_IFRS9_R04A -- A0411 - A0417 - A0419 - A0420 - A0424 - R04A_MOV_419
B11: R04A_MOV_420_24 | C11: V1.01_Credito_IFRS9_R04A -- A0411 - A0417 - A0419 - A0420 - A0424 - R04A_MOV_420_24 | D11: Falta integrar informacion Contable
B12: FILE_CFEN | C12: LAYOUT CFEN-3 | D12: Contabilidad Falta info Capital FundamentalAnexo 1 O

Sheet Resumen
B2: NumReportes | C2: EstatusAct
B3: AreaApoyo | C3: Valida Areas | D3: US-Mapeo | E3: DES-Desarrollo Txt | F3: US-Validación Txt | G3: US-VoBo | H3: BW-Ejecucion | I3: Envío Vacio | J3: Total general
B4: BajaWare | H4: 8 | J4: 8
B5: Contabilidad | D5: 4 | E5: 1 | F5: 1 | G5: 10 | J5: 16
B6: Finanzas | D6: 8 | J6: 8
B7: Operaciones | E7: 4 | J7: 4
B8: Producto | G8: 42 | J8: 42
B9: Riesgos | C9: 6 | D9: 4 | E9: 3 | G9: 6 | J9: 19
B10: Tesoreria | D10: 31 | E10: 1 | I10: 12 | J10: 44
B11: TI | E11: 14 | J11: 14
B12: UNE | D12: 1 | J12: 1
B13: Tesoreria/Contabilidad | D13: 1 | J13: 1
B14: Total general | C14: 6 | D14: 49 | E14: 23 | F14: 1 | G14: 58 | H14: 8 | I14: 12 | J14: 157
I16: 145 | J16: total en presentacion
I17: =I16+GETPIVOTDATA("Carpeta",$B$2,"EstatusAct","Envío Vacio") -> 157
G18: =H17-E4 -> 0
B19: i: En validacion con BW, si proceden (productos que no se operan y reporte dado de baja en portal BANXICO)
B20: ii: Corresponde a 2 reportes
B21: iii: La mayoria se ataca con el reporte de transacciones | G21: =G17/G18 -> #DIV/0!
B22: iv: 10 generacion automática Bajaware
B23: v: 1 campo en validacion de cada reporte con Riesgos

Sheet Relacion  (2)
U1: ASIGNACION AREA | W1: MAPEO | Y1: DESARROLLO | AA1: VALIDACION US | AC1: VOBO LAYOUT | AE1: EJECUCION BW | AG1: VOBO EJECUCION | AI1: FEBRERO | AM1: MARZO | AQ1: ABRIL | AV1: MAYO
A2: Carpeta | B2: Area | C2: Responsable | D2: Azure | E2: Pestañas | F2: Layout | G2: Estatus | H2: Comentarios | I2: Revision VoBo Usuario | J2: Actualizacion | K2: EstatusAct | L2: Sts2 | M2: Desarrollo | N2: AreaApoyo | O2: Obs Add | P2: Obs Add2 | Q2: NO APLICA | R2: Motivo No APLICA | T2: # | U2: INICIO | V2: FIN | W2: INICIO | X2: FIN | Y2: INICIO | Z2: FIN | AA2: INICIO | AB2: FIN | AC2: INICIO | AD2: FIN | AE2: INICIO | AF2: FIN | AG2: INICIO | AH2: FIN | AI2: 02 - 0 6 | AJ2: 09 - 13 | AK2: 16 - 20 | AL2: 23 - 27 | AM2: 02 - 0 6 | AN2: 09 - 13 | AO2: 16 - 20 | AP2: 23 - 27 | AQ2: 30 - 03 | AR2: 06 - 10 | AS2: 13 - 17 | AT2: 20 - 24 | AU2: 27 - 01 | AV2: 04 - 08 | AW2: 11 - 15 | AX2: 18 - 22 | AY2: 25 - 29
A3: Adicionales | B3: Tesorería | C3: Eduardo Cabral | D3: MAPEO | E3: VENC_ANT_REPORTOS | F3: Layout_REPORTOS_MN_ME_V7_2024 -- REPORTOS | G3: Pendiente | H3: Modulo de tesoreria | I3: NTT | K3: US-Mapeo | L3: Ext NTT | M3: Int Tesoreria | N3: Tesoreria | O3: Layout_REPORTOS_MN_ME_V7 -- REPORTOS | P3: modif nomb layout | T3: 1 | W3: 46056 | X3: 46087 | Y3: 46083 | Z3: 46122 | AA3: 46111 | AB3: 46136 | AC3: 46118 | AD3: 46136 | AE3: 46125 | AF3: 46150 | AG3: 46139 | AH3: 46171
A4: Adicionales | B4: Captacion | C4: Arturo Angeles | D4: MAPEO | E4: USUARIOS NO CLIENTES BE | F4: R1522_USUARIOS NO CLIENTES BE_V0.4 -- R15 1522 | G4: No mapeado | K4: US-Mapeo | M4: Interno | N4: Finanzas | T4: 2 | W4: 46056 | X4: 46080 | Y4: 46083 | Z4: 46108 | AA4: 46111 | AB4: 46122 | AC4: 46121 | AD4: 46122 | AE4: 46125 | AF4: 46143 | AG4: 46146 | AH4: 46157
A5: Operativos | B5: Operaciones Captacion | C5: Luis Alberto | D5: CERRADA | E5: UBICACION DE PUNTOS DE TRANSACC | F5: R2443_Ubicacion - R2443 | G5: No mapeado | H5: NTT | K5: Envío Vacio | L5: NA | M5: NA | N5: NA | O5: Acuerdo con Erika el 18/12/24. No aplica en este momento, porque no tendremos nada de lo que solicita. | Q5: No aplica | R5: Este reporte recaba información respecto a la ubicación geográfica de las sucursales, módulos, cajeros automáticos, terminales punto de venta y comisionistas a través de las cuales los usuarios de los servicios financieros realizan las transacciones. | T5: 3
A6: Operativos | B6: Operaciones Captacion | C6: Luis Alberto | D6: DESARROLLO | E6: TITULARES GARANTIZADOS | F6: R2423_IFRS9_Titulares_Garantizados_V0.4 -- R2423 | G6: No mapeado | H6: NTT | K6: DES-Desarrollo Txt | L6: Ext NTT | M6: Externo | N6: Operaciones | S6: x | T6: 4 | Y6: 46056 | Z6: 46073 | AA6: 46076 | AB6: 46094 | AC6: 46093 | AD6: 46094 | AE6: 46097 | AF6: 46115 | AG6: 46118 | AH6: 46136
A7: Adicionales | B7: Operaciones Captacion | C7: Luis Alberto | E7: TADESCOM_BAJAS | F7: Layout TADESCOM -- TADESCOM | G7: NA | H7: NA | K7: Backlog | L7: NA | M7: NA | N7: NA | T7: 5
A8: Adicionales | B8: Operaciones Captacion | C8: Luis Alberto | E8: TADESCOM_ALTAS | F8: Layout TADESCOM -- TADESCOM | G8: NA | H8: NA | K8: Backlog | L8: NA | M8: NA | N8: NA | T8: 6
A9: Adicionales | B9: Tesorería | C9: Eduardo Cabral | D9: MAPEO | E9: SWAPS | F9: Layout_SWAPS_V9 -- SWAPS | G9: Pendiente | H9: Modulo de tesoreria | I9: NTT | K9: US-Mapeo | L9: Ext NTT | M9: Int Tesoreria | N9: Tesoreria | O9: Layout_SWAPS_V9.1 -- SWAPS | P9: modif nomb layout | T9: 7 | W9: 46056 | X9: 46087 | Y9: 46083 | Z9: 46122 | AA9: 46111 | AB9: 46136 | AC9: 46118 | AD9: 46136 | AE9: 46125 | AF9: 46150 | AG9: 46139 | AH9: 46171
A10: Adicionales | B10: Tesorería | C10: Eduardo Cabral | D10: MAPEO | E10: SWAP_MEREC_CONVO | F10: Layout_SWAPS_V9 -- SWAPS | G10: Pendiente | H10: Modulo de tesoreria | I10: NTT | K10: US-Mapeo | L10: Ext NTT | M10: Int Tesoreria | N10: Tesoreria | O10: Layout_SWAPS_V9.1 -- SWAPS - 1. ENT_SWAP_MEREC_CONVO | P10: modif nomb layout | T10: 8 | W10: 46056 | X10: 46087 | Y10: 46083 | Z10: 46122 | AA10: 46111 | AB10: 46136 | AC10: 46118 | AD10: 46136 | AE10: 46125 | AF10: 46150 | AG10: 46139 | AH10: 46171
A11: Adicionales | B11: Tesorería | C11: Eduardo Cabral | D11: MAPEO | E11: SWAP_IV_COM | F11: Layout_SWAPS_V9 -- SWAPS | G11: Pendiente | H11: Modulo de tesoreria | I11: NTT | K11: US-Mapeo | L11: Ext NTT | M11: Int Tesoreria | N11: Tesoreria | O11: Layout_SWAPS_V9.1 -- SWAPS | P11: modif nomb layout | T11: 9 | W11: 46056 | X11: 46087 | Y11: 46083 | Z11: 46122 | AA11: 46111 | AB11: 46136 | AC11: 46118 | AD11: 46136 | AE11: 46125 | AF11: 46150 | AG11: 46139 | AH11: 46171
A12: Adicionales | B12: Tesorería | C12: Eduardo Cabral | D12: MAPEO | E12: SWAP_IV | F12: Layout_SWAPS_V9 -- SWAPS | G12: Pendiente | H12: Modulo de tesoreria | I12: NTT | K12: US-Mapeo | L12: Ext NTT | M12: Int Tesoreria | N12: Tesoreria | O12: Layout_SWAPS_V9.1 -- SWAPS | P12: modif nomb layout | T12: 10 | W12: 46056 | X12: 46087 | Y12: 46083 | Z12: 46122 | AA12: 46111 | AB12: 46136 | AC12: 46118 | AD12: 46136 | AE12: 46125 | AF12: 46150 | AG12: 46139 | AH12: 46171
A13: Adicionales | B13: Tesorería | C13: Eduardo Cabral | D13: MAPEO | E13: SWAP_I | F13: Layout_SWAPS_V9 -- SWAPS | G13: Pendiente | H13: Modulo de tesoreria | I13: NTT | K13: US-Mapeo | L13: Ext NTT | M13: Int Tesoreria | N13: Tesoreria | O13: Layout_SWAPS_V9.1 -- SWAPS | P13: modif nomb layout | T13: 11 | W13: 46056 | X13: 46087 | Y13: 46083 | Z13: 46122 | AA13: 46111 | AB13: 46136 | AC13: 46118 | AD13: 46136 | AE13: 46125 | AF13: 46150 | AG13: 46139 | AH13: 46171
A14: Adicionales | B14: Tesorería | C14: Eduardo Cabral | D14: MAPEO | E14: SWAP_FLUJOS | F14: Layout_SWAPS_V9 -- SWAPS | G14: Pendiente | H14: Modulo de tesoreria | I14: NTT | K14: US-Mapeo | L14: Ext NTT | M14: Int Tesoreria | N14: Tesoreria | O14: Layout_SWAPS_V9.1 -- SWAPS | P14: modif nomb layout | T14: 12 | W14: 46056 | X14: 46087 | Y14: 46083 | Z14: 46122 | AA14: 46111 | AB14: 46136 | AC14: 46118 | AD14: 46136 | AE14: 46125 | AF14: 46150 | AG14: 46139 | AH14: 46171
A15: Adicionales | B15: Tesorería | C15: Eduardo Cabral | D15: MAPEO | E15: SWAP_CUOTAS_INT | F15: Layout_SWAPS_V9 -- SWAPS | G15: Pendiente | H15: Modulo de tesoreria | I15: NTT | K15: US-Mapeo | L15: Ext NTT | M15: Int Tesoreria | N15: Tesoreria | O15: Layout_SWAPS_V9.1 -- SWAPS | P15: modif nomb layout | T15: 13 | W15: 46056 | X15: 46087 | Y15: 46083 | Z15: 46122 | AA15: 46111 | AB15: 46136 | AC15: 46118 | AD15: 46136 | AE15: 46125 | AF15: 46150 | AG15: 46139 | AH15: 46171
A16: Adicionales | B16: Tesorería | C16: Eduardo Cabral | D16: MAPEO | E16: SWAP_CONVO | F16: Layout_SWAPS_V9 -- SWAPS | G16: Pendiente | H16: Modulo de tesoreria | I16: NTT | K16: US-Mapeo | L16: Ext NTT | M16: Int Tesoreria | N16: Tesoreria | O16: Layout_SWAPS_V9.1 -- SWAPS | P16: modif nomb layout | T16: 14 | W16: 46056 | X16: 46087 | Y16: 46083 | Z16: 46122 | AA16: 46111 | AB16: 46136 | AC16: 46118 | AD16: 46136 | AE16: 46125 | AF16: 46150 | AG16: 46139 | AH16: 46171
A17: Operativos | B17: Operaciones Captacion | C17: Luis Alberto | D17: CERRADA | E17: SUCURSALES | F17: R2422_Sucursales -- R2422 | G17: No mapeado | H17: NTT | K17: Envío Vacio | L17: NA | M17: NA | N17: NA | O17: Acuerdo con Erika el 18/12/24. No aplica en este momento, porque no tendremos nada de lo que solicita. | Q17: No aplica | R17: Se refiere a tarjetas, ATM, TPVs, y No. de personal, no tenemos esos datos actualmente, por lo que consideramos que no nos aplica actualmente, pero debemos cerrarlo en conjunto. | T17: 15
A18: Operativos | B18: Producto | C18: Claudia Barroso | E18: SEGUROS NOMINA Y PERS | F18: CUP -- CUP | G18: NA | H18: NA | K18: Backlog | L18: NA | M18: NA | N18: NA | T18: 16
A19: Adicionales | B19: Tesorería | C19: Eduardo Cabral | D19: CERRADA | E19: SECCION 2E | F19: Layouts Garantias de Liquidez -- GL | G19: Pendiente | H19: Modulo de tesoreria | I19: NTT | K19: Envío Vacio | L19: NA | M19: NA | N19: NA | O19: Calificaciones Otorgadas (No aplica confirma Denisse) | P19: Finanzas | Q19: No aplica | R19: Comentario Bajaware: Si no cuentan con las operaciones a las que se refiere ese layout, no es necesario llenarlo. Sin embargo, si Banxico da de alta el producto en el portal de Espifnet, tendrían que enviarlo vacío. | T19: 17
A20: Adicionales | B20: Tesorería | C20: Eduardo Cabral | D20: CERRADA | E20: SECCION 2D | F20: Layouts Garantias de Liquidez -- GL | G20: Pendiente | H20: Modulo de tesoreria | I20: NTT | K20: Envío Vacio | L20: NA | M20: NA | N20: NA | O20: Inmuebles | P20: Finanzas/Contabilidad/WO | Q20: No aplica | R20: Comentario Bajaware: Si no cuentan con las operaciones a las que se refiere ese layout, no es necesario llenarlo. Sin embargo, si Banxico da de alta el producto en el portal de Espifnet, tendrían que enviarlo vacío. | T20: 18
A21: Adicionales | B21: Tesorería | C21: Eduardo Cabral | D21: CERRADA | E21: SECCION 2C | F21: Layouts Garantias de Liquidez -- GL | G21: Pendiente | H21: Modulo de tesoreria | I21: NTT | K21: Envío Vacio | L21: NA | M21: NA | N21: NA | O21: Acciones | P21: Tesoreria | Q21: No aplica | R21: Comentario Bajaware: Si no cuentan con las operaciones a las que se refiere ese layout, no es necesario llenarlo. Sin embargo, si Banxico da de alta el producto en el portal de Espifnet, tendrían que enviarlo vacío. | T21: 19
A22: Adicionales | B22: Tesorería | C22: Eduardo Cabral | D22: CERRADA | E22: SECCION 2B | F22: Layouts Garantias de Liquidez -- GL | G22: Pendiente | H22: Modulo de tesoreria | I22: NTT | K22: Envío Vacio | L22: NA | M22: NA | N22: NA | O22: Cartera de Créditos | P22: Operaciones | Q22: No aplica | R22: Comentario Bajaware: Si no cuentan con las operaciones a las que se refiere ese layout, no es necesario llenarlo. Sin embargo, si Banxico da de alta el producto en el portal de Espifnet, tendrían que enviarlo vacío. | T22: 20
A23: Adicionales | B23: Tesorería | C23: Eduardo Cabral | D23: CERRADA | E23: SECCION 2A | F23: Layouts Garantias de Liquidez -- GL | G23: Pendiente | H23: Modulo de tesoreria | I23: NTT | K23: Envío Vacio | L23: NA | M23: NA | N23: NA | O23: Cartera de Valores | P23: Tesoreria | Q23: No aplica | R23: Comentario Bajaware: Si no cuentan con las operaciones a las que se refiere ese layout, no es necesario llenarlo. Sin embargo, si Banxico da de alta el producto en el portal de Espifnet, tendrían que enviarlo vacío. | T23: 21
A24: Adicionales | B24: Tesorería | C24: Eduardo Cabral | D24: CERRADA | E24: SECCION 1 | F24: Layouts Garantias de Liquidez -- GL | G24: Pendiente | H24: Modulo de tesoreria | I24: NTT | K24: Envío Vacio | L24: NA | M24: NA | N24: NA | O24: Layouts Garantias de Liquidez | P24: Financiamiento | Q24: No aplica | R24: Comentario Bajaware: Si no cuentan con las operaciones a las que se refiere ese layout, no es necesario llenarlo. Sin embargo, si Banxico da de alta el producto en el portal de Espifnet, tendrían que enviarlo vacío. | T24: 22
A25: Adicionales | B25: Tesorería | C25: Eduardo Cabral | D25: MAPEO | E25: REPORTOS_MNME | F25: Layout_REPORTOS_MN_ME_V7_2024 -- REPORTOS | G25: Pendiente | H25: Modulo de tesoreria | I25: NTT | K25: US-Mapeo | L25: Ext NTT | M25: Int Tesoreria | N25: Tesoreria | O25: Layout_REPORTOS_MN_ME_V7 -- REPORTOS | P25: modif nomb layout | T25: 23 | W25: 46056 | X25: 46087 | Y25: 46083 | Z25: 46122 | AA25: 46111 | AB25: 46136 | AC25: 46118 | AD25: 46136 | AE25: 46125 | AF25: 46150 | AG25: 46139 | AH25: 46171
A26: Cartera | B26: Operaciones Credito | C26: Luis Alberto | E26: REL_CONSUMO_GARANTIA | F26: V1.05_Credito_IFRS9_Consumo_Completo VF (2) | G26: NA | H26: NA | K26: Backlog | L26: NA | M26: NA | N26: NA | T26: 24
A27: Operativos | B27: Producto | C27: Claudia Barroso | D27: VOBO US | E27: Registro Gral Prd | F27: CUP -- CUP | G27: Listo | H27: VoBo Dado por el usuario (No se cuenta con informacion) | I27: Estructura | K27: US-VoBo | M27: Interno | N27: Producto | T27: 25 | AE27: 46076 | AF27: 46101 | AG27: 46104 | AH27: 46129
A28: Captacion | B28: Producto | C28: Claudia Barroso | D28: DESARROLLO | E28: RECO | F28: Layout RECO BW -- RECO | G28: Listo | H28: Ntt, ya se reviso txt por usuario VoBo | I28: Estructura y universo | J28: Se reasignó a Prodcuto | estaba identificado como VoBo Usuario | K28: DES-Desarrollo Txt | M28: Interno | N28: TI | O28: Se menciona a NTT | P28: Validar la parte de captación NTT para integrar en un solo reporte | S28: x | T28: 26 | Y28: 46056 | Z28: 46080 | AA28: 46083 | AB28: 46108 | AC28: 46107 | AD28: 46108 | AE28: 46111 | AF28: 46136 | AG28: 46139 | AH28: 46164
A29: Situacion Finaciera | B29: Contabilidad | C29: Ramon Jaimes | D29: VOBO US | E29: RECLASIFICACIONES | F29: R10_RECLASIFICACIONES -- R10 | G29: Listo | H29: Revision de txt por parte del usuario | I29: Estructura y universo | J29: Duda US ¿Cuál sería la mecánica para la generación de este reporte? | K29: US-VoBo | M29: Interno | N29: Contabilidad | T29: 27 | AE29: 46076 | AF29: 46101 | AG29: 46104 | AH29: 46129
A30: Operativos | B30: Operaciones Captacion | C30: Luis Alberto | D30: CERRADA | E30: RECLAMACIONES BURSATILES BM | F30: R2711_ReclamacionesB_V0.4 | G30: NA | H30: NA | K30: Backlog | L30: NA | M30: NA | N30: NA | O30: Estaba asiugnado a NTT | T30: 28
A31: Adicionales | B31: UNE | C31: Martin Roman | D31: MAPEO | E31: RECLAMACIONES | F31: LAYOUT R27_V1 -- R27 - 2701 | G31: No mapeado | K31: US-Mapeo | M31: Interno | N31: UNE | T31: 29 | W31: 46056 | X31: 46094 | Y31: 46097 | Z31: 46115 | AA31: 46118 | AB31: 46129 | AC31: 46128 | AD31: 46129 | AE31: 46132 | AF31: 46150 | AG31: 46153 | AH31: 46171
A32: Adicionales | B32: Contabilidad | C32: Ramon Jaimes | D32: VOBO US | E32: R36_PAGOS_ANT_CARGOS_DIF | F32: V1.00_R3601_CARGOS_DIF_PAGOS_ANTICIPADOS -- R36 3601 | G32: Por iniciar | H32: Se requiere recepcion de requerimiento y Excel. (Usuario) | K32: US-VoBo | M32: Interno | N32: Contabilidad | T32: 30 | AE32: 46076 | AF32: 46101 | AG32: 46104 | AH32: 46129
A33: Adicionales | B33: Riesgos | C33: Homero Sanchez | D33: MAPEO | E33: R35_1 | F33: Layout R35_1 -- R35 | G33: No mapeado | H33: Se tiene que realizar una vez migrado a Banco | se puede mapear la cartera de creditos -- Riesgos / Exp Valores Transac -- Tesoreria | I33: Estructura y universo | K33: US-Mapeo | M33: Interno | N33: Riesgos | T33: 31 | AE33: 46111 | AF33: 46136 | AG33: 46139 | AH33: 46157
A34: Adicionales | B34: Operaciones Captacion | C34: Luis Alberto | D34: CERRADA | E34: R26OPE | F34: R26 Comisionistas -- R26 2610 2611 2612 2616 | G34: No mapeado | H34: NTT | K34: Envío Vacio | L34: NA | M34: NA | N34: NA | O34: Acuerdo con Erika el 18/12/24. No aplica en este momento, porque no tendremos nada de lo que solicita. | Q34: No aplica | R34: Actualmente no tenemos comisionistas, esta información no se puede generar por el momento, nosotros decimos que no nos aplica, pero debemos cerrarlo en conjunto. | T34: 32
