Workbook

Sheet Inicio
B2: SISTEMA DE COTIZACIONES Y CONTROL DE CLIENTES
B3: Ing. César Gutiérrez Francisco · Persona Física con Actividad Empresarial
B5: RESUMEN
B6: Cotizaciones registradas | E6: Monto total cotizado
B7: =COUNTIF(Cotizaciones!$A$2:$A$200,"?*") -> 3 | E7: =SUM(Cotizaciones!$K$2:$K$200) -> 108849.76
B9: Cotizaciones aceptadas | E9: Monto aceptado
B10: =COUNTIF(Cotizaciones!$O$2:$O$200,"Aceptada") -> 1 | E10: =SUMIF(Cotizaciones!$O$2:$O$200,"Aceptada",Cotizaciones!$K$2:$K$200) -> 23552.64
B12: Enviadas (pendientes) | E12: Tasa de conversión
B13: =COUNTIF(Cotizaciones!$O$2:$O$200,"Enviada") -> 2 | E13: =IFERROR(COUNTIF(Cotizaciones!$O$2:$O$200,"Aceptada")/COUNTIF(Cotizaciones!$A$2:$A$200,"?*"),0) -> 0.33333333
B15: CÓMO USAR
B16: 1. Config: pon tus datos, datos bancarios y revisa las tasas fiscales (una sola vez).
B17: 2. Clientes: registra cada cliente y elige su Tratamiento fiscal (PF, empresa, honorarios o RESICO).
B18: 3. Servicios: guarda tus servicios y precios para reutilizarlos.
B19: 4. Generador: elige el cliente, captura los conceptos y la hoja calcula impuestos y total. Expórtala a PDF y envíala.
B20: 5. Cotizaciones: copia el resumen (al pie del Generador) para llevar el control de todo.
B22: Nota fiscal: el sistema distingue lo FACTURADO (CFDI) de lo que RECIBES en el banco (neto de retenciones). No es asesoría fiscal; valida tu régimen y retenciones con tu contador.

Sheet Generador
B1: CG | D1: =Config!$C$5 -> Ing. César Gutiérrez Francisco
D2: ="RFC: "&Config!$C$6 -> RFC: GUFC880124S88
D3: =Config!$C$8 -> 1ra Privada El Mirador 5, Amp. Nativitas, Xochimilco, CDMX, C.P. 16450
B4: Servicios Profesionales de TI | D4: ="Tel: "&Config!$C$9 -> Tel: 55 3274 5538 / 55 2962 2655
D5: =Config!$C$10 -> cesar.gutierrez@programadoresjava.mx
B7: COTIZACIÓN
B8: FOLIO | C8: FECHA | E8: VIGENCIA (días) | F8: VENCE
B9: =Config!$C$27&TEXT(Config!$C$28,"0000") -> GUFC-0003 | C9: 46177 | E9: 15 | F9: =C9+E9 -> 46192
B11: DATOS DEL CLIENTE
B12: Cliente | C12: DISH México
B13: RFC | C13: =IFERROR(IF(INDEX(Clientes!$D$2:$D$200,MATCH($C$12,Clientes!$B$2:$B$200,0))=0,"",INDEX(Clientes!$D$2:$D$200,MATCH($C$12,Clientes!$B$2:$B$200,0))),"") | E13: Tipo | F13: =IFERROR(IF(INDEX(Clientes!$C$2:$C$200,MATCH($C$12,Clientes!$B$2:$B$200,0))=0,"",INDEX(Clientes!$C$2:$C$200,MATCH($C$12,Clientes!$B$2:$B$200,0))),"") -> PM
B14: Contacto | C14: =IFERROR(IF(INDEX(Clientes!$G$2:$G$200,MATCH($C$12,Clientes!$B$2:$B$200,0))=0,"",INDEX(Clientes!$G$2:$G$200,MATCH($C$12,Clientes!$B$2:$B$200,0))),"") -> Carlos Robles | E14: Teléfono | F14: =IFERROR(IF(INDEX(Clientes!$I$2:$I$200,MATCH($C$12,Clientes!$B$2:$B$200,0))=0,"",INDEX(Clientes!$I$2:$I$200,MATCH($C$12,Clientes!$B$2:$B$200,0))),"")
B15: Correo | C15: =IFERROR(IF(INDEX(Clientes!$H$2:$H$200,MATCH($C$12,Clientes!$B$2:$B$200,0))=0,"",INDEX(Clientes!$H$2:$H$200,MATCH($C$12,Clientes!$B$2:$B$200,0))),"") -> carlos.robles@dish.com.mx
B17: DESCRIPCIÓN | C17: UNIDAD | D17: CANT. | E17: P. UNITARIO | F17: IMPORTE
B18: Menú IVR principal + corrección de versiones + estandarización de certificados | C18: Servicio | D18: 1 | E18: 8742 | F18: =IF(OR($D18="",$E18=""),"",$D18*$E18) -> 8742
F19: =IF(OR($D19="",$E19=""),"",$D19*$E19)
F20: =IF(OR($D20="",$E20=""),"",$D20*$E20)
F21: =IF(OR($D21="",$E21=""),"",$D21*$E21)
F22: =IF(OR($D22="",$E22=""),"",$D22*$E22)
F23: =IF(OR($D23="",$E23=""),"",$D23*$E23)
F24: =IF(OR($D24="",$E24=""),"",$D24*$E24)
F25: =IF(OR($D25="",$E25=""),"",$D25*$E25)
F26: =IF(OR($D26="",$E26=""),"",$D26*$E26)
F27: =IF(OR($D27="",$E27=""),"",$D27*$E27)
B29: Tratamiento fiscal aplicado | C29: Cliente PM - Servicios Profesionales | E29: Subtotal | F29: =SUM(F18:F27) -> 8742
B30: ="Predeterminado del cliente: "&IFERROR(INDEX(Clientes!$F$2:$F$200,MATCH($C$12,Clientes!$B$2:$B$200,0)),"") -> Predeterminado del cliente: Cliente PM - Servicios Profesionales | E30: IVA | F30: =$F$29*Config!$C$15 -> 1398.72
B31: IVA ret. % (si Personalizado) | C31: 0 | E31: (-) IVA retenido | F31: =IF($C$29="Cliente PM - Servicios Profesionales",$F$29*Config!$C$16,IF($C$29="Personalizado",$F$29*$C$31,0)) -> 932.48
B32: ISR ret. % (si Personalizado) | C32: 0 | E32: (-) ISR retenido | F32: =IF($C$29="Cliente PM - Servicios Profesionales",$F$29*Config!$C$17,IF($C$29="Cliente PM - RESICO PF",$F$29*Config!$C$18,IF($C$29="Personalizado",$F$29*$C$32,0))) -> 874.2
E33: TOTAL FACTURADO (CFDI) | F33: =$F$29+F30 -> 10140.72
E34: TOTAL A RECIBIR | F34: =$F$29+F30-F31-F32 -> 8334.04
B36: CONDICIONES COMERCIALES
B37: ="• Vigencia de la cotización: "&E9&" días naturales (vence "&TEXT(F9,"dd/mm/yyyy")&")." -> • Vigencia de la cotización: 15 días naturales (vence 19/06/2026).
B38: "• Precios expresados en pesos mexicanos (MXN)."
B39: "• Forma de pago: 50% al inicio y 50% contra entrega, salvo acuerdo distinto."
B40: "• Garantía de 30 días naturales sobre los servicios entregados."
B41: ="• Pago a: "&Config!$C$22&" — "&Config!$C$21&" | Cuenta: "&Config!$C$23&" | CLABE: "&Config!$C$24 -> • Pago a: César Gutiérrez Francisco — BBVA Bancomer | Cuenta: 1568791856 | CLABE: 012180015687918560
B42: "• Cualquier cambio no considerado en esta cotización se cotiza por separado."
B44: _______________________________ | E44: _______________________________
B45: =Config!$C$5 -> Ing. César Gutiérrez Francisco | E45: Aceptación del cliente
B46: El Prestador | E46: Nombre y firma
...

Sheet Cotizaciones
A1: Folio | B1: Fecha | C1: Cliente | D1: Tipo | E1: Tratamiento fiscal | F1: Concepto | G1: Subtotal | H1: IVA | I1: IVA Ret. | J1: ISR Ret. | K1: Total Facturado | L1: Total a Recibir | M1: Vig. (días) | N1: Vence | O1: Estatus | P1: Notas
A2: GUFC-DIS202601 | B2: 46107 | C2: DISH México | D2: PM | E2: Cliente PM - Servicios Profesionales | F2: Menú IVR principal + corrección de versiones + estandarización de certificados | G2: 8742 | H2: =IF($G2="","",$G2*Config!$C$15) -> 1398.72 | I2: =IF($G2="","",IF($E2="Cliente PM - Servicios Profesionales",$G2*Config!$C$16,0)) -> 932.48 | J2: =IF($G2="","",IF($E2="Cliente PM - Servicios Profesionales",$G2*Config!$C$17,IF($E2="Cliente PM - RESICO PF",$G2*Config!$C$18,0))) -> 874.2 | K2: =IF($G2="","",$G2+$H2) -> 10140.72 | L2: =IF($G2="","",$K2-$I2-$J2) -> 8334.04 | M2: 15 | N2: =IF(OR($B2="",$M2=""),"",$B2+$M2) -> 46122 | O2: Enviada | P2: PF→PM corregido (con retenciones). Facturado igual; cambia lo que recibes.
A3: GECO-3411 | B3: 44281 | C3: CNAT / DISH | D3: PM | E3: Cliente PM - Servicios Profesionales | F3: Modificaciones IVR On Internet: clasificación inalámbrico/alámbrico/satelital | G3: 20304 | H3: =IF($G3="","",$G3*Config!$C$15) -> 3248.64 | I3: =IF($G3="","",IF($E3="Cliente PM - Servicios Profesionales",$G3*Config!$C$16,0)) -> 2165.76 | J3: =IF($G3="","",IF($E3="Cliente PM - Servicios Profesionales",$G3*Config!$C$17,IF($E3="Cliente PM - RESICO PF",$G3*Config!$C$18,0))) -> 2030.4 | K3: =IF($G3="","",$G3+$H3) -> 23552.64 | L3: =IF($G3="","",$K3-$I3-$J3) -> 19356.48 | M3: 30 | N3: =IF(OR($B3="",$M3=""),"",$B3+$M3) -> 44311 | O3: Aceptada | P3: PF→PM corregido (con retenciones).
A4: GUFC-TP202602 | B4: 46140 | C4: Teleperformance | D4: PM | E4: Cliente PM - Servicios Profesionales | F4: Reinstalación de CMS primario (Avaya) considerando el CMS secundario: instalación de 1 instancia de CMS, migración y sincronización (62 h) | G4: 64790 | H4: =IF($G4="","",$G4*Config!$C$15) -> 10366.4 | I4: =IF($G4="","",IF($E4="Cliente PM - Servicios Profesionales",$G4*Config!$C$16,0)) -> 6910.9333 | J4: =IF($G4="","",IF($E4="Cliente PM - Servicios Profesionales",$G4*Config!$C$17,IF($E4="Cliente PM - RESICO PF",$G4*Config!$C$18,0))) -> 6479 | K4: =IF($G4="","",$G4+$H4) -> 75156.4 | L4: =IF($G4="","",$K4-$I4-$J4) -> 61766.467 | M4: 30 | N4: =IF(OR($B4="",$M4=""),"",$B4+$M4) -> 46170 | O4: Enviada | P4: PF→PM. Recreada como cotización propia (origen: formato Comunicación Artificial).
H5: =IF($G5="","",$G5*Config!$C$15) | I5: =IF($G5="","",IF($E5="Cliente PM - Servicios Profesionales",$G5*Config!$C$16,0)) | J5: =IF($G5="","",IF($E5="Cliente PM - Servicios Profesionales",$G5*Config!$C$17,IF($E5="Cliente PM - RESICO PF",$G5*Config!$C$18,0))) | K5: =IF($G5="","",$G5+$H5) | L5: =IF($G5="","",$K5-$I5-$J5) | N5: =IF(OR($B5="",$M5=""),"",$B5+$M5)
H6: =IF($G6="","",$G6*Config!$C$15) | I6: =IF($G6="","",IF($E6="Cliente PM - Servicios Profesionales",$G6*Config!$C$16,0)) | J6: =IF($G6="","",IF($E6="Cliente PM - Servicios Profesionales",$G6*Config!$C$17,IF($E6="Cliente PM - RESICO PF",$G6*Config!$C$18,0))) | K6: =IF($G6="","",$G6+$H6) | L6: =IF($G6="","",$K6-$I6-$J6) | N6: =IF(OR($B6="",$M6=""),"",$B6+$M6)
H7: =IF($G7="","",$G7*Config!$C$15) | I7: =IF($G7="","",IF($E7="Cliente PM - Servicios Profesionales",$G7*Config!$C$16,0)) | J7: =IF($G7="","",IF($E7="Cliente PM - Servicios Profesionales",$G7*Config!$C$17,IF($E7="Cliente PM - RESICO PF",$G7*Config!$C$18,0))) | K7: =IF($G7="","",$G7+$H7) | L7: =IF($G7="","",$K7-$I7-$J7) | N7: =IF(OR($B7="",$M7=""),"",$B7+$M7)
H8: =IF($G8="","",$G8*Config!$C$15) | I8: =IF($G8="","",IF($E8="Cliente PM - Servicios Profesionales",$G8*Config!$C$16,0)) | J8: =IF($G8="","",IF($E8="Cliente PM - Servicios Profesionales",$G8*Config!$C$17,IF($E8="Cliente PM - RESICO PF",$G8*Config!$C$18,0))) | K8: =IF($G8="","",$G8+$H8) | L8: =IF($G8="","",$K8-$I8-$J8) | N8: =IF(OR($B8="",$M8=""),"",$B8+$M8)
H9: =IF($G9="","",$G9*Config!$C$15) | I9: =IF($G9="","",IF($E9="Cliente PM - Servicios Profesionales",$G9*Config!$C$16,0)) | J9: =IF($G9="","",IF($E9="Cliente PM - Servicios Profesionales",$G9*Config!$C$17,IF($E9="Cliente PM - RESICO PF",$G9*Config!$C$18,0))) | K9: =IF($G9="","",$G9+$H9) | L9: =IF($G9="","",$K9-$I9-$J9) | N9: =IF(OR($B9="",$M9=""),"",$B9+$M9)
H10: =IF($G10="","",$G10*Config!$C$15) | I10: =IF($G10="","",IF($E10="Cliente PM - Servicios Profesionales",$G10*Config!$C$16,0)) | J10: =IF($G10="","",IF($E10="Cliente PM - Servicios Profesionales",$G10*Config!$C$17,IF($E10="Cliente PM - RESICO PF",$G10*Config!$C$18,0))) | K10: =IF($G10="","",$G10+$H10) | L10: =IF($G10="","",$K10-$I10-$J10) | N10: =IF(OR($B10="",$M10=""),"",$B10+$M10)
H11: =IF($G11="","",$G11*Config!$C$15) | I11: =IF($G11="","",IF($E11="Cliente PM - Servicios Profesionales",$G11*Config!$C$16,0)) | J11: =IF($G11="","",IF($E11="Cliente PM - Servicios Profesionales",$G11*Config!$C$17,IF($E11="Cliente PM - RESICO PF",$G11*Config!$C$18,0))) | K11: =IF($G11="","",$G11+$H11) | L11: =IF($G11="","",$K11-$I11-$J11) | N11: =IF(OR($B11="",$M11=""),"",$B11+$M11)
H12: =IF($G12="","",$G12*Config!$C$15) | I12: =IF($G12="","",IF($E12="Cliente PM - Servicios Profesionales",$G12*Config!$C$16,0)) | J12: =IF($G12="","",IF($E12="Cliente PM - Servicios Profesionales",$G12*Config!$C$17,IF($E12="Cliente PM - RESICO PF",$G12*Config!$C$18,0))) | K12: =IF($G12="","",$G12+$H12) | L12: =IF($G12="","",$K12-$I12-$J12) | N12: =IF(OR($B12="",$M12=""),"",$B12+$M12)
H13: =IF($G13="","",$G13*Config!$C$15) | I13: =IF($G13="","",IF($E13="Cliente PM - Servicios Profesionales",$G13*Config!$C$16,0)) | J13: =IF($G13="","",IF($E13="Cliente PM - Servicios Profesionales",$G13*Config!$C$17,IF($E13="Cliente PM - RESICO PF",$G13*Config!$C$18,0))) | K13: =IF($G13="","",$G13+$H13) | L13: =IF($G13="","",$K13-$I13-$J13) | N13: =IF(OR($B13="",$M13=""),"",$B13+$M13)
H14: =IF($G14="","",$G14*Config!$C$15) | I14: =IF($G14="","",IF($E14="Cliente PM - Servicios Profesionales",$G14*Config!$C$16,0)) | J14: =IF($G14="","",IF($E14="Cliente PM - Servicios Profesionales",$G14*Config!$C$17,IF($E14="Cliente PM - RESICO PF",$G14*Config!$C$18,0))) | K14: =IF($G14="","",$G14+$H14) | L14: =IF($G14="","",$K14-$I14-$J14) | N14: =IF(OR($B14="",$M14=""),"",$B14+$M14)
H15: =IF($G15="","",$G15*Config!$C$15) | I15: =IF($G15="","",IF($E15="Cliente PM - Servicios Profesionales",$G15*Config!$C$16,0)) | J15: =IF($G15="","",IF($E15="Cliente PM - Servicios Profesionales",$G15*Config!$C$17,IF($E15="Cliente PM - RESICO PF",$G15*Config!$C$18,0))) | K15: =IF($G15="","",$G15+$H15) | L15: =IF($G15="","",$K15-$I15-$J15) | N15: =IF(OR($B15="",$M15=""),"",$B15+$M15)
H16: =IF($G16="","",$G16*Config!$C$15) | I16: =IF($G16="","",IF($E16="Cliente PM - Servicios Profesionales",$G16*Config!$C$16,0)) | J16: =IF($G16="","",IF($E16="Cliente PM - Servicios Profesionales",$G16*Config!$C$17,IF($E16="Cliente PM - RESICO PF",$G16*Config!$C$18,0))) | K16: =IF($G16="","",$G16+$H16) | L16: =IF($G16="","",$K16-$I16-$J16) | N16: =IF(OR($B16="",$M16=""),"",$B16+$M16)
... H59: =IF($G59="","",$G59*Config!$C$15) | I59: =IF($G59="","",IF($E59="Cliente PM - Servicios Profesionales",$G59*Config!$C$16,0)) | J59: =IF($G59="","",IF($E59="Cliente PM - Servicios Profesionales",$G59*Config!$C$17,IF($E59="Cliente PM - RESICO PF",$G59*Config!$C$18,0))) | K59: =IF($G59="","",$G59+$H59) | L59: =IF($G59="","",$K59-$I59-$J59) | N59: =IF(OR($B59="",$M59=""),"",$B59+$M59)

Sheet Clientes
A1: Clave | B1: Nombre / Razón Social | C1: Tipo | D1: RFC | E1: Régimen fiscal | F1: Tratamiento fiscal | G1: Contacto | H1: Correo | I1: Teléfono | J1: Domicilio | K1: Notas
A2: CLI-001 | B2: DISH México | C2: PM | E2: Régimen General | F2: Cliente PM - Servicios Profesionales | G2: Carlos Robles | H2: carlos.robles@dish.com.mx | K2: Cliente actual IVR
A3: CLI-002 | B3: CNAT, S. de R.L. de C.V. | C3: PM | E3: Régimen General | F3: Cliente PM - Servicios Profesionales | G3: Lic. Carlos A. Cárdenas Castro | K3: Contratante anexos IVR
A4: CLI-003 | B4: Hispanic Teleservices de Guadalajara, S.A. de C.V. | C4: PM | D4: HTG050509RJ5 | E4: Régimen General | F4: Cliente PM - Servicios Profesionales | G4: Lic. Manuel Laborde Aguirre | J4: Periférico Pte. M. Gómez Morín 7651-A, Zapopan, Jal., C.P. 45012 | K4: Contrato marco 2019
A5: CLI-004 | B5: (Ejemplo) Cliente Persona Física | C5: PF | E5: RESICO PF | F5: Cliente PF (Persona Física) | K5: Borrar / editar
A6: CLI-005 | B6: Teleperformance | C6: PM | E6: Régimen General | F6: Cliente PM - Servicios Profesionales | G6: Ing. Sergio Cobos Herrera | I6: (+52) 813-405-8709 | J6: Monterrey, NL, México | K6: Reinstalación CMS Avaya

Sheet Servicios
A1: Clave | B1: Descripción | C1: Unidad | D1: Precio Unitario | E1: Notas
A2: SRV-001 | B2: Hora de desarrollo / programación | C2: Hora | D2: 846 | E2: Tarifa base histórica
A3: SRV-002 | B3: Análisis de requerimientos | C3: Hora | D3: 846
A4: SRV-003 | B4: Pruebas / corrección | C4: Hora | D4: 846
A5: SRV-004 | B5: Configuración productiva | C5: Hora | D5: 846
A6: SRV-005 | B6: Documentación / memoria técnica | C6: Hora | D6: 846
A7: SRV-006 | B7: Agregar menú en IVR + configuración | C7: Servicio | D7: 4742 | E7: Cotización GUFC-DIS
A8: SRV-007 | B8: Menú IVR + corrección de versiones + estandarización de certificados | C8: Servicio | D8: 8742 | E8: Cotización actual
A9: SRV-008 | B9: Soporte / mantenimiento mensual | C9: Mes | D9: 0 | E9: Definir
A10: SRV-009 | B10: Hora especializada Avaya CMS / System Manager | C10: Hora | D10: 1045 | E10: Cotización Teleperformance

Sheet Config
B2: CONFIGURACIÓN GENERAL
B4: 1 · DATOS DEL PRESTADOR (aparecen en la cotización)
B5: Nombre / Razón social | C5: Ing. César Gutiérrez Francisco
B6: RFC | C6: GUFC880124S88
B7: Régimen fiscal | C7: Persona Física con Actividad Empresarial
B8: Domicilio | C8: 1ra Privada El Mirador 5, Amp. Nativitas, Xochimilco, CDMX, C.P. 16450
B9: Teléfono | C9: 55 3274 5538 / 55 2962 2655
B10: Correo | C10: cesar.gutierrez@programadoresjava.mx
B11: Correo 2 | C11: manuel.martinez@programadoresjava.mx
B12: Lema / Giro | C12: Servicios Profesionales de Desarrollo e Integración de Sistemas
B14: 2 · PARÁMETROS FISCALES (edítalos si cambia la ley)
B15: IVA | C15: 0.16 | D15: Tasa general
B16: IVA retenido (Serv. Profesionales) | C16: 0.10666667 | D16: 2/3 del IVA
B17: ISR retenido (Serv. Profesionales) | C17: 0.1 | D17: Honorarios PF→PM
B18: ISR retenido (RESICO PF) | C18: 0.0125 | D18: PM retiene a RESICO PF
B20: 3 · DATOS BANCARIOS (para la cotización)
B21: Banco | C21: BBVA Bancomer
B22: Beneficiario | C22: César Gutiérrez Francisco
B23: No. de cuenta | C23: 1568791856
B24: CLABE | C24: 012180015687918560
B26: 4 · FOLIO
B27: Prefijo de folio | C27: GUFC-
B28: Siguiente consecutivo | C28: 3
B30: ⚠ Aviso: las tasas anteriores son referenciales (vigentes en México). No constituyen asesoría fiscal. Confirma tu régimen y retenciones aplicables con tu contador y ajusta estos parámetros una sola vez; todo el sistema se recalcula solo.

Sheet Listas
A1: Tipo | B1: Tratamiento | C1: Estatus | D1: Unidad
A2: PF | B2: Cliente PF (Persona Física) | C2: Borrador | D2: Servicio
A3: PM | B3: Cliente PM - Actividad Empresarial | C3: Enviada | D3: Hora
B4: Cliente PM - Servicios Profesionales | C4: Aceptada | D4: Día
B5: Cliente PM - RESICO PF | C5: Rechazada | D5: Proyecto
B6: Personalizado | C6: Vencida | D6: Pieza
C7: Facturada/Pagada | D7: Mes
D8: Licencia
